<?xml version="1.0" ?>
<robot name="robotis_mini">
  <!--
  <xacro:property name="MESHVOLUME_DMFB01" value="19027.634766" />
  <xacro:property name="MESHVOLUME_DMBB02" value="17309.392578" />
  <xacro:property name="MESHVOLUME_DMFB03" value="4172.618164" />
  <xacro:property name="MESHVOLUME_DMFB04" value="5622.555664" />
  <xacro:property name="MESHVOLUME_DMFB05" value="8814.262695" />
  <xacro:property name="MESHVOLUME_DMFB06" value="13174.791992" />
  <xacro:property name="MESHVOLUME_DMFB07" value="6234.946777" />
  <xacro:property name="MESHVOLUME_DMFF01" value="14216.210938" />
  <xacro:property name="MESHVOLUME_SPU5"   value="690.421204" />
  <xacro:property name="MESHVOLUME_SPD3B3" value="508.287537" />
  <xacro:property name="MESHVOLUME_SPD3B5" value="862.646484" />
  <xacro:property name="MESHVOLUME_SPD3B7" value="1217.040894" />
  <xacro:property name="MESHVOLUME_SPD4B5" value="1157.969116" />
  <xacro:property name="MESHVOLUME_SPD7V4" value="1055.941406" />
  <xacro:property name="MESHVOLUME_SPL2B2" value="591.031128" />
  <xacro:property name="MESHVOLUME_SPO5"   value="511.205475" />
  <xacro:property name="MESHVOLUME_XL320"  value="16403.394531" />
  -->
  <link name="base_link"/>
  <joint name="body_skeleton_joint" type="fixed">
    <origin rpy="1.5707963267948966 0 1.5707963267948966" xyz="0 0 0"/>
    <parent link="base_link"/>
    <child link="body_skeleton_link"/>
  </joint>
  <link name="body_skeleton_link">
    <visual>
      <origin rpy="0 0 0" xyz="0 0 0"/>
      <geometry>
        <mesh filename="../meshes/DMB-B02(W).stl" scale="0.001 0.001 0.001"/>
      </geometry>
    </visual>
    <inertial>
      <origin rpy="0 0 0" xyz="0.0 8.773967e-3 -22.151331e-3"/>
      <mass value="0.021"/>
      <inertia ixx="1.7308808225304e-05" ixy="0.0" ixz="0.0" iyy="1.82893689077532e-05" iyz="-7.8512796293769e-06" izz="1.8014198076767998e-05"/>
    </inertial>
    <collision>
      <geometry>
        <mesh filename="../meshes/DMB-B02(W)_s.stl" scale="0.001 0.001 0.001"/>
      </geometry>
    </collision>
  </link>
  <joint name="body_torso_joint" type="fixed">
    <origin rpy="0 0 0" xyz="0 0.042 -0.015"/>
    <parent link="body_skeleton_link"/>
    <child link="body_torso_link"/>
  </joint>
  <link name="body_torso_link">
    <visual>
      <origin rpy="0 0 0" xyz="0 0 0"/>
      <geometry>
        <mesh filename="../meshes/DMF-B01(W).stl" scale="0.001 0.001 0.001"/>
      </geometry>
    </visual>
    <inertial>
      <origin rpy="0 0 0" xyz="0.000442e-3 2.022341e-3 8.475896e-3"/>
      <mass value="0.026"/>
      <inertia ixx="2.63422620164562e-05" ixy="6.233248538059739e-11" ixz="-3.0917572282723615e-10" iyy="3.35044398459192e-05" iyz="7.6726522692246e-06" izz="2.4608528477188198e-05"/>
    </inertial>
    <collision>
      <geometry>
        <mesh filename="../meshes/DMF-B01(W)_s.stl" scale="0.001 0.001 0.001"/>
      </geometry>
    </collision>
  </link>
  <joint name="body_back_joint" type="fixed">
    <origin rpy="0 0 0" xyz="0 0.011 -0.032"/>
    <parent link="body_skeleton_link"/>
    <child link="body_back_link"/>
  </joint>
  <link name="body_back_link">
    <visual>
      <origin rpy="0 0 0" xyz="0 0 0"/>
      <geometry>
        <box size="0.07 0.022 0.022"/>
      </geometry>
    </visual>
    <inertial>
      <origin rpy="0 0 0" xyz="0.0 0.0 0.0"/>
      <mass value="0.056"/>
      <inertia ixx="4.5173333333333325e-06" ixy="0.0" ixz="0.0" iyy="2.5125333333333338e-05" iyz="0.0" izz="2.5125333333333338e-05"/>
    </inertial>
    <collision>
      <geometry>
        <box size="0.07 0.022 0.022"/>
      </geometry>
    </collision>
  </link>
  <joint name="body_chest_joint" type="fixed">
    <origin rpy="0 0 0" xyz="0 0.016 -0.004"/>
    <parent link="body_skeleton_link"/>
    <child link="body_chest_link"/>
  </joint>
  <link name="body_chest_link">
    <visual>
      <origin rpy="0 0 0" xyz="0 0 0"/>
      <geometry>
        <box size="0.07 0.022 0.022"/>
      </geometry>
    </visual>
    <inertial>
      <origin rpy="0 0 0" xyz="0.0 0.0 0.0"/>
      <mass value="0.056"/>
      <inertia ixx="4.5173333333333325e-06" ixy="0.0" ixz="0.0" iyy="2.5125333333333338e-05" iyz="0.0" izz="2.5125333333333338e-05"/>
    </inertial>
    <collision>
      <geometry>
        <box size="0.07 0.022 0.022"/>
      </geometry>
    </collision>
  </link>
  <joint name="neck_axis_joint" type="fixed">
    <origin rpy="1.5707963267948966 0 0" xyz="0 0.036 0.006"/>
    <parent link="body_torso_link"/>
    <child link="neck_axis_link"/>
  </joint>
  <link name="neck_axis_link">
    <inertial>
      <mass value="0.0001"/>
      <inertia ixx="1.0e-12" ixy="0.0" ixz="0.0" iyy="1.0e-12" iyz="0.0" izz="1.0e-12"/>
    </inertial>
  </link>
  <joint name="neck_joint" type="revolute"> <!--fixed-->
    <axis xyz="0 0 1"/>
    <limit effort="0.1" lower="-1.5707963267948966" upper="1.5707963267948966" velocity="11.938052083641214"/>  <!--remove this line if joint is fixed-->
    <origin rpy="0 0 0" xyz="0 0 0"/>
    <parent link="neck_axis_link"/>
    <child link="neck_link"/>
  </joint>
  <link name="neck_link">
    <visual>
      <origin rpy="0 0 0" xyz="0 0 0"/>
      <geometry>
        <mesh filename="../meshes/XL-320D.stl" scale="0.001 0.001 0.001"/>
      </geometry>
    </visual>
    <inertial>
      <origin rpy="0 0 0" xyz="0.0 -6.745858e-3 0.697233e-3"/>
      <mass value="0.02"/>
      <inertia ixx="2.8169401796846998e-06" ixy="0.0" ixz="0.0" iyy="1.8687826796735248e-06" iyz="-9.755271144975289e-08" izz="2.442679644825487e-06"/>
    </inertial>
    <collision>
      <geometry>
        <mesh filename="../meshes/XL-320D.stl" scale="0.001 0.001 0.001"/>
      </geometry>
    </collision>
  </link>
  <joint name="body_head_joint" type="fixed">
    <origin rpy="-1.5707963267948966 0 0" xyz="0 0 0.003"/>
    <parent link="neck_link"/>
    <child link="body_head_link"/>
  </joint>
  <link name="body_head_link">
    <visual>
      <origin rpy="0 0 0" xyz="0 0 0"/>
      <geometry>
        <mesh filename="../meshes/DMF-F01(W).stl" scale="0.001 0.001 0.001"/>
      </geometry>
    </visual>
    <inertial>
      <origin rpy="0 0 0" xyz="0.000021e-3 14.665582e-3 -8.712881e-3"/>
      <mass value="0.017"/>
      <inertia ixx="7.51745423623215e-06" ixy="0.0" ixz="0.0" iyy="8.3491950342813e-06" iyz="1.7379035510682749e-06" izz="8.396329982309849e-06"/>
    </inertial>
    <collision>
      <geometry>
        <mesh filename="../meshes/DMF-F01(W)_s.stl" scale="0.001 0.001 0.001"/>
      </geometry>
    </collision>
  </link>
  <joint name="l_shoulder_anchor_joint" type="fixed">
    <origin rpy="1.5707963267948966 0 1.5707963267948966" xyz="0.024 0.042 0.009"/>
    <parent link="body_skeleton_link"/>
    <child link="l_shoulder_anchor_link"/>
  </joint>
  <link name="l_shoulder_anchor_link">
    <visual>
      <origin rpy="0 0 0" xyz="0 0 0"/>
      <geometry>
        <mesh filename="../meshes/SPU-5(W).stl" scale="0.001 0.001 0.001"/>
      </geometry>
    </visual>
    <inertial>
      <origin rpy="0 0 0" xyz="0.0 1.31172e-3 0.0"/>
      <mass value="0.001"/>
      <inertia ixx="2.7160998812739677e-08" ixy="0.0" ixz="0.0" iyy="5.2595636134718856e-08" iyz="0.0" izz="2.8058676756667802e-08"/>
    </inertial>
    <collision>
      <geometry>
        <mesh filename="../meshes/SPU-5(W)_s.stl" scale="0.001 0.001 0.001"/>
      </geometry>
    </collision>
  </link>
  <joint name="r_shoulder_anchor_joint" type="fixed">
    <origin rpy="1.5707963267948966 0 1.5707963267948966" xyz="-0.024 0.042 0.009"/>
    <parent link="body_skeleton_link"/>
    <child link="r_shoulder_anchor_link"/>
  </joint>
  <link name="r_shoulder_anchor_link">
    <visual>
      <origin rpy="0 0 0" xyz="0 0 0"/>
      <geometry>
        <mesh filename="../meshes/SPU-5(W).stl" scale="0.001 0.001 0.001"/>
      </geometry>
    </visual>
    <inertial>
      <origin rpy="0 0 0" xyz="0.0 1.31172e-3 0.0"/>
      <mass value="0.001"/>
      <inertia ixx="2.7160998812739677e-08" ixy="0.0" ixz="0.0" iyy="5.2595636134718856e-08" iyz="0.0" izz="2.8058676756667802e-08"/>
    </inertial>
    <collision>
      <geometry>
        <mesh filename="../meshes/SPU-5(W)_s.stl" scale="0.001 0.001 0.001"/>
      </geometry>
    </collision>
  </link>
  <joint name="l_hip_anchor_joint" type="fixed">
    <origin rpy="0 0 0" xyz="0.024 -0.006 -0.033"/>
    <parent link="body_skeleton_link"/>
    <child link="l_hip_anchor_link"/>
  </joint>
  <link name="l_hip_anchor_link">
    <visual>
      <origin rpy="0 0 0" xyz="0 0 0"/>
      <geometry>
        <mesh filename="../meshes/SPU-5(W).stl" scale="0.001 0.001 0.001"/>
      </geometry>
    </visual>
    <inertial>
      <origin rpy="0 0 0" xyz="0.0 1.31172e-3 0.0"/>
      <mass value="0.001"/>
      <inertia ixx="2.7160998812739677e-08" ixy="0.0" ixz="0.0" iyy="5.2595636134718856e-08" iyz="0.0" izz="2.8058676756667802e-08"/>
    </inertial>
    <collision>
      <geometry>
        <mesh filename="../meshes/SPU-5(W)_s.stl" scale="0.001 0.001 0.001"/>
      </geometry>
    </collision>
  </link>
  <joint name="r_hip_anchor_joint" type="fixed">
    <origin rpy="0 0 0" xyz="-0.024 -0.006 -0.033"/>
    <parent link="body_skeleton_link"/>
    <child link="r_hip_anchor_link"/>
  </joint>
  <link name="r_hip_anchor_link">
    <visual>
      <origin rpy="0 0 0" xyz="0 0 0"/>
      <geometry>
        <mesh filename="../meshes/SPU-5(W).stl" scale="0.001 0.001 0.001"/>
      </geometry>
    </visual>
    <inertial>
      <origin rpy="0 0 0" xyz="0.0 1.31172e-3 0.0"/>
      <mass value="0.001"/>
      <inertia ixx="2.7160998812739677e-08" ixy="0.0" ixz="0.0" iyy="5.2595636134718856e-08" iyz="0.0" izz="2.8058676756667802e-08"/>
    </inertial>
    <collision>
      <geometry>
        <mesh filename="../meshes/SPU-5(W)_s.stl" scale="0.001 0.001 0.001"/>
      </geometry>
    </collision>
  </link>
  <joint name="l_shoulder_servo_joint" type="fixed">
    <origin rpy="0.0 0 3.141592653589793" xyz="0 -0.024 0"/>
    <parent link="l_shoulder_anchor_link"/>
    <child link="l_shoulder_servo_link"/>
  </joint>
  <link name="l_shoulder_servo_link">
    <visual>
      <origin rpy="0 0 0" xyz="0 0 0"/>
      <geometry>
        <mesh filename="../meshes/XL-320D.stl" scale="0.001 0.001 0.001"/>
      </geometry>
    </visual>
    <inertial>
      <origin rpy="0 0 0" xyz="0.0 -6.745858e-3 0.697233e-3"/>
      <mass value="0.02"/>
      <inertia ixx="2.8169401796846998e-06" ixy="0.0" ixz="0.0" iyy="1.8687826796735248e-06" iyz="-9.755271144975289e-08" izz="2.442679644825487e-06"/>
    </inertial>
    <collision>
      <geometry>
        <mesh filename="../meshes/XL-320D.stl" scale="0.001 0.001 0.001"/>
      </geometry>
    </collision>
  </link>
  <joint name="l_shoulder_joint" type="revolute">
    <axis xyz="0 0 -1"/>
    <limit effort="0.39" lower="-1.5707963267948966" upper="1.5707963267948966" velocity="11.938052083641214"/>
    <origin rpy="0 0 0" xyz="0 0 0"/>
    <parent link="l_shoulder_servo_link"/>
    <child link="l_shoulder_link"/>
    <!--
      <dynamics damping="${XL320_DAMPING}" />
      -->
  </joint>
  <link name="l_shoulder_link">
    <inertial>
      <mass value="0.0001"/>
      <inertia ixx="1.0e-12" ixy="0.0" ixz="0.0" iyy="1.0e-12" iyz="0.0" izz="1.0e-12"/>
    </inertial>
  </link>
  <transmission name="l_shoulder_tran">
    <type>transmission_interface/SimpleTransmission</type>
    <joint name="l_shoulder_joint">
      <hardwareInterface>EffortJointInterface</hardwareInterface>
    </joint>
    <actuator name="l_shoulder_motor">
      <hardwareInterface>EffortJointInterface</hardwareInterface>
      <mechanicalReduction>1</mechanicalReduction>
    </actuator>
  </transmission>
  <joint name="l_biceps_anchor_joint" type="fixed">
    <origin rpy="1.5707963267948966 0 -1.5707963267948966" xyz="0.012 0 0.033"/>
    <parent link="l_shoulder_link"/>
    <child link="l_biceps_anchor_link"/>
  </joint>
  <link name="l_biceps_anchor_link">
    <visual>
      <origin rpy="0 0 0" xyz="0 0 0"/>
      <geometry>
        <mesh filename="../meshes/DMF-B03(W).stl" scale="0.001 0.001 0.001"/>
      </geometry>
    </visual>
    <inertial>
      <origin rpy="0 0 0" xyz="0.0 -8.846923e-3 7.432426e-3"/>
      <mass value="0.005"/>
      <inertia ixx="5.893486671099843e-07" ixy="0.0" ixz="0.0" iyy="1.3682831066650124e-06" iyz="1.5691252989899708e-07" izz="1.371564647677275e-06"/>
    </inertial>
    <collision>
      <geometry>
        <mesh filename="../meshes/DMF-B03(W)_s.stl" scale="0.001 0.001 0.001"/>
      </geometry>
    </collision>
  </link>
  <joint name="l_biceps_axis_joint" type="fixed">
    <origin rpy="1.5707963267948966 0 1.5707963267948966" xyz="0 0 0"/>
    <parent link="l_biceps_anchor_link"/>
    <child link="l_biceps_axis_link"/>
  </joint>
  <link name="l_biceps_axis_link">
    <inertial>
      <mass value="0.0001"/>
      <inertia ixx="1.0e-12" ixy="0.0" ixz="0.0" iyy="1.0e-12" iyz="0.0" izz="1.0e-12"/>
    </inertial>
  </link>
  <joint name="l_biceps_joint" type="revolute">
    <axis xyz="0 0 -1"/>
    <limit effort="0.39" lower="-1.5707963267948966" upper="1.5707963267948966" velocity="11.938052083641214"/>
    <origin rpy="0 0 1.5707963267948966" xyz="0 0 0"/>
    <parent link="l_biceps_axis_link"/>
    <child link="l_biceps_link"/>
    <!--
      <dynamics damping="${XL320_DAMPING}" />
      -->
  </joint>
  <link name="l_biceps_link">
    <visual>
      <origin rpy="0 0 0" xyz="0 0 0"/>
      <geometry>
        <mesh filename="../meshes/XL-320D.stl" scale="0.001 0.001 0.001"/>
      </geometry>
    </visual>
    <inertial>
      <origin rpy="0 0 0" xyz="0.0 -6.745858e-3 0.697233e-3"/>
      <mass value="0.02"/>
      <inertia ixx="2.8169401796846998e-06" ixy="0.0" ixz="0.0" iyy="1.8687826796735248e-06" iyz="-9.755271144975289e-08" izz="2.442679644825487e-06"/>
    </inertial>
    <collision>
      <geometry>
        <mesh filename="../meshes/XL-320D.stl" scale="0.001 0.001 0.001"/>
      </geometry>
    </collision>
  </link>
  <transmission name="l_biceps_tran">
    <type>transmission_interface/SimpleTransmission</type>
    <joint name="l_biceps_joint">
      <hardwareInterface>EffortJointInterface</hardwareInterface>
    </joint>
    <actuator name="l_biceps_motor">
      <hardwareInterface>EffortJointInterface</hardwareInterface>
      <mechanicalReduction>1</mechanicalReduction>
    </actuator>
  </transmission>
  <joint name="l_biceps_spo_joint" type="fixed">
    <origin rpy="1.5707963267948966 0 0" xyz="0 0 -0.015"/>
    <parent link="l_biceps_link"/>
    <child link="l_biceps_spo_link"/>
  </joint>
  <link name="l_biceps_spo_link">
    <visual>
      <origin rpy="0 0 0" xyz="0 0 0"/>
      <geometry>
        <mesh filename="../meshes/SPO-5(GR).stl" scale="0.001 0.001 0.001"/>
      </geometry>
    </visual>
    <inertial>
      <origin rpy="0 0 0" xyz="-0.004686e-3 1.501381e-3 -0.004686e-3"/>
      <mass value="0.001"/>
      <inertia ixx="1.511699541429177e-08" ixy="-3.7907332468947e-12" ixz="1.2866184946294198e-11" iyy="2.9213253615331356e-08" iyz="-3.7907092213548e-12" izz="1.511699541429177e-08"/>
    </inertial>
    <collision>
      <geometry>
        <mesh filename="../meshes/SPO-5(GR)_s.stl" scale="0.001 0.001 0.001"/>
      </geometry>
    </collision>
  </link>
  <joint name="l_upper_arm_joint" type="fixed">
    <origin rpy="3.141592653589793 -1.5707963267948966 0" xyz="0 -0.045 0"/>
    <parent link="l_biceps_link"/>
    <child link="l_upper_arm_link"/>
  </joint>
  <link name="l_upper_arm_link">
    <visual>
      <origin rpy="0 0 0" xyz="0 0 0"/>
      <geometry>
        <mesh filename="../meshes/DMF-B04(W).stl" scale="0.001 0.001 0.001"/>
      </geometry>
    </visual>
    <inertial>
      <origin rpy="0 0 0" xyz="0.0 -16.650940e-3 3.893445e-3"/>
      <mass value="0.007"/>
      <inertia ixx="1.4844145053407249e-06" ixy="0.0" ixz="0.0" iyy="1.5912567135270748e-06" iyz="3.5247996037499997e-07" izz="2.3466465586526997e-06"/>
    </inertial>
    <collision>
      <geometry>
        <mesh filename="../meshes/DMF-B04(W)_s.stl" scale="0.001 0.001 0.001"/>
      </geometry>
    </collision>
  </link>
  <joint name="l_elbow_axis_joint" type="fixed">
    <origin rpy="3.141592653589793 -1.5707963267948966 0" xyz="0 0 0"/>
    <parent link="l_upper_arm_link"/>
    <child link="l_elbow_axis_link"/>
  </joint>
  <link name="l_elbow_axis_link">
    <inertial>
      <mass value="0.0001"/>
      <inertia ixx="1.0e-12" ixy="0.0" ixz="0.0" iyy="1.0e-12" iyz="0.0" izz="1.0e-12"/>
    </inertial>
  </link>
  <joint name="l_elbow_joint" type="revolute">
    <axis xyz="0 0 -1"/>
    <limit effort="0.39" lower="-1.5707963267948966" upper="1.5707963267948966" velocity="11.938052083641214"/>
    <origin rpy="0 0 0" xyz="0 0 0"/>
    <parent link="l_elbow_axis_link"/>
    <child link="l_elbow_link"/>
    <!--
      <dynamics damping="${XL320_DAMPING}" />
      -->
  </joint>
  <link name="l_elbow_link">
    <visual>
      <origin rpy="0 0 0" xyz="0 0 0"/>
      <geometry>
        <mesh filename="../meshes/XL-320D.stl" scale="0.001 0.001 0.001"/>
      </geometry>
    </visual>
    <inertial>
      <origin rpy="0 0 0" xyz="0.0 -6.745858e-3 0.697233e-3"/>
      <mass value="0.02"/>
      <inertia ixx="2.8169401796846998e-06" ixy="0.0" ixz="0.0" iyy="1.8687826796735248e-06" iyz="-9.755271144975289e-08" izz="2.442679644825487e-06"/>
    </inertial>
    <collision>
      <geometry>
        <mesh filename="../meshes/XL-320D.stl" scale="0.001 0.001 0.001"/>
      </geometry>
    </collision>
  </link>
  <transmission name="l_elbow_tran">
    <type>transmission_interface/SimpleTransmission</type>
    <joint name="l_elbow_joint">
      <hardwareInterface>EffortJointInterface</hardwareInterface>
    </joint>
    <actuator name="l_elbow_motor">
      <hardwareInterface>EffortJointInterface</hardwareInterface>
      <mechanicalReduction>1</mechanicalReduction>
    </actuator>
  </transmission>
  <joint name="l_elbow_spo_joint" type="fixed">
    <origin rpy="1.5707963267948966 0 0" xyz="0 0 -0.015"/>
    <parent link="l_elbow_link"/>
    <child link="l_elbow_spo_link"/>
  </joint>
  <link name="l_elbow_spo_link">
    <visual>
      <origin rpy="0 0 0" xyz="0 0 0"/>
      <geometry>
        <mesh filename="../meshes/SPO-5(GR).stl" scale="0.001 0.001 0.001"/>
      </geometry>
    </visual>
    <inertial>
      <origin rpy="0 0 0" xyz="-0.004686e-3 1.501381e-3 -0.004686e-3"/>
      <mass value="0.001"/>
      <inertia ixx="1.511699541429177e-08" ixy="-3.7907332468947e-12" ixz="1.2866184946294198e-11" iyy="2.9213253615331356e-08" iyz="-3.7907092213548e-12" izz="1.511699541429177e-08"/>
    </inertial>
    <collision>
      <geometry>
        <mesh filename="../meshes/SPO-5(GR)_s.stl" scale="0.001 0.001 0.001"/>
      </geometry>
    </collision>
  </link>
  <joint name="l_lower_arm_joint" type="fixed">
    <origin rpy="0 3.141592653589793 3.141592653589793" xyz="0 -0.024 0"/>
    <parent link="l_elbow_link"/>
    <child link="l_lower_arm_link"/>
  </joint>
  <link name="l_lower_arm_link">
    <visual>
      <origin rpy="0 0 0" xyz="0 0 0"/>
      <geometry>
        <mesh filename="../meshes/SPU-5(W).stl" scale="0.001 0.001 0.001"/>
      </geometry>
    </visual>
    <inertial>
      <origin rpy="0 0 0" xyz="0.0 1.31172e-3 0.0"/>
      <mass value="0.001"/>
      <inertia ixx="2.7160998812739677e-08" ixy="0.0" ixz="0.0" iyy="5.2595636134718856e-08" iyz="0.0" izz="2.8058676756667802e-08"/>
    </inertial>
    <collision>
      <geometry>
        <mesh filename="../meshes/SPU-5(W)_s.stl" scale="0.001 0.001 0.001"/>
      </geometry>
    </collision>
  </link>
  <joint name="l_wrist_anchor_joint" type="fixed">
    <origin rpy="0 0 0" xyz="0 0.0045 0"/>
    <parent link="l_lower_arm_link"/>
    <child link="l_wrist_anchor_link"/>
  </joint>
  <link name="l_wrist_anchor_link">
    <visual>
      <origin rpy="0 0 0" xyz="0 0 0"/>
      <geometry>
        <mesh filename="../meshes/SPD-3B3(W).stl" scale="0.001 0.001 0.001"/>
      </geometry>
    </visual>
    <inertial>
      <origin rpy="0 0 0" xyz="0.0 0.0 0.0"/>
      <mass value="0.001"/>
      <inertia ixx="1.7427879176605523e-08" ixy="0.0" ixz="0.0" iyy="3.4023619651757087e-08" iyz="0.0" izz="1.7427879176605523e-08"/>
    </inertial>
    <collision>
      <geometry>
        <mesh filename="../meshes/SPD-3B3(W)_s.stl" scale="0.001 0.001 0.001"/>
      </geometry>
    </collision>
  </link>
  <joint name="l_hand_wrist1_joint" type="fixed">
    <origin rpy="0 0 0" xyz="0 0.0015 0"/>
    <parent link="l_wrist_anchor_link"/>
    <child link="l_hand_wrist1_link"/>
  </joint>
  <link name="l_hand_wrist1_link">
    <visual>
      <origin rpy="0 0 0" xyz="0 0 0"/>
      <geometry>
        <mesh filename="../meshes/SPO-5(GR).stl" scale="0.001 0.001 0.001"/>
      </geometry>
    </visual>
    <inertial>
      <origin rpy="0 0 0" xyz="-0.004686e-3 1.501381e-3 -0.004686e-3"/>
      <mass value="0.001"/>
      <inertia ixx="1.511699541429177e-08" ixy="-3.7907332468947e-12" ixz="1.2866184946294198e-11" iyy="2.9213253615331356e-08" iyz="-3.7907092213548e-12" izz="1.511699541429177e-08"/>
    </inertial>
    <collision>
      <geometry>
        <mesh filename="../meshes/SPO-5(GR)_s.stl" scale="0.001 0.001 0.001"/>
      </geometry>
    </collision>
  </link>
  <joint name="l_hand_wrist2_joint" type="fixed">
    <origin rpy="0 0 0" xyz="0 0.003 0"/>
    <parent link="l_hand_wrist1_link"/>
    <child link="l_hand_wrist2_link"/>
  </joint>
  <link name="l_hand_wrist2_link">
    <visual>
      <origin rpy="0 0 0" xyz="0 0 0"/>
      <geometry>
        <mesh filename="../meshes/SPO-5(GR).stl" scale="0.001 0.001 0.001"/>
      </geometry>
    </visual>
    <inertial>
      <origin rpy="0 0 0" xyz="-0.004686e-3 1.501381e-3 -0.004686e-3"/>
      <mass value="0.001"/>
      <inertia ixx="1.511699541429177e-08" ixy="-3.7907332468947e-12" ixz="1.2866184946294198e-11" iyy="2.9213253615331356e-08" iyz="-3.7907092213548e-12" izz="1.511699541429177e-08"/>
    </inertial>
    <collision>
      <geometry>
        <mesh filename="../meshes/SPO-5(GR)_s.stl" scale="0.001 0.001 0.001"/>
      </geometry>
    </collision>
  </link>
  <joint name="l_hand_base_joint" type="fixed">
    <origin rpy="0 1.5707963267948966 0" xyz="0 0.0045 0"/>
    <parent link="l_hand_wrist2_link"/>
    <child link="l_hand_base_link"/>
  </joint>
  <link name="l_hand_base_link">
    <visual>
      <origin rpy="0 0 0" xyz="0 0 0"/>
      <geometry>
        <mesh filename="../meshes/SPD-3B5(W).stl" scale="0.001 0.001 0.001"/>
      </geometry>
    </visual>
    <inertial>
      <origin rpy="0 0 0" xyz="0.0 0.0 0.0"/>
      <mass value="0.001"/>
      <inertia ixx="3.042659030468979e-08" ixy="0.0" ixz="0.0" iyy="1.0920534527495155e-07" iyz="0.0" izz="8.019504918581541e-08"/>
    </inertial>
    <collision>
      <geometry>
        <mesh filename="../meshes/SPD-3B5(W)_s.stl" scale="0.001 0.001 0.001"/>
      </geometry>
    </collision>
  </link>
  <joint name="l_hand_thumb_joint" type="fixed">
    <origin rpy="1.5707963267948966 3.141592653589793 0" xyz="0.018 0.0015 -0.009"/>
    <parent link="l_hand_base_link"/>
    <child link="l_hand_thumb_link"/>
  </joint>
  <link name="l_hand_thumb_link">
    <visual>
      <origin rpy="0 0 0" xyz="0 0 0"/>
      <geometry>
        <mesh filename="../meshes/SPL-2B2(W).stl" scale="0.001 0.001 0.001"/>
      </geometry>
    </visual>
    <inertial>
      <origin rpy="0 0 0" xyz="3.975824e-3 0.0 -5.846319e-3"/>
      <mass value="0.001"/>
      <inertia ixx="2.989443002947031e-08" ixy="0.0" ixz="-8.274710338510628e-09" iyy="3.2062954811316346e-08" iyz="0.0" izz="2.0928228446149052e-08"/>
    </inertial>
    <collision>
      <geometry>
        <mesh filename="../meshes/SPL-2B2(W)_s.stl" scale="0.001 0.001 0.001"/>
      </geometry>
    </collision>
  </link>
  <joint name="l_hand_palm_anchor1_joint" type="fixed">
    <origin rpy="1.5707963267948966 1.5707963267948966 0" xyz="0.003 0.0015 0.012"/>
    <parent link="l_hand_base_link"/>
    <child link="l_hand_palm_anchor1_link"/>
  </joint>
  <link name="l_hand_palm_anchor1_link">
    <visual>
      <origin rpy="0 0 0" xyz="0 0 0"/>
      <geometry>
        <mesh filename="../meshes/SPL-2B2(W).stl" scale="0.001 0.001 0.001"/>
      </geometry>
    </visual>
    <inertial>
      <origin rpy="0 0 0" xyz="3.975824e-3 0.0 -5.846319e-3"/>
      <mass value="0.001"/>
      <inertia ixx="2.989443002947031e-08" ixy="0.0" ixz="-8.274710338510628e-09" iyy="3.2062954811316346e-08" iyz="0.0" izz="2.0928228446149052e-08"/>
    </inertial>
    <collision>
      <geometry>
        <mesh filename="../meshes/SPL-2B2(W)_s.stl" scale="0.001 0.001 0.001"/>
      </geometry>
    </collision>
  </link>
  <joint name="l_hand_palm_anchor2_joint" type="fixed">
    <origin rpy="1.5707963267948966 1.5707963267948966 0" xyz="-0.009 0.0015 0.012"/>
    <parent link="l_hand_base_link"/>
    <child link="l_hand_palm_anchor2_link"/>
  </joint>
  <link name="l_hand_palm_anchor2_link">
    <visual>
      <origin rpy="0 0 0" xyz="0 0 0"/>
      <geometry>
        <mesh filename="../meshes/SPL-2B2(W).stl" scale="0.001 0.001 0.001"/>
      </geometry>
    </visual>
    <inertial>
      <origin rpy="0 0 0" xyz="3.975824e-3 0.0 -5.846319e-3"/>
      <mass value="0.001"/>
      <inertia ixx="2.989443002947031e-08" ixy="0.0" ixz="-8.274710338510628e-09" iyy="3.2062954811316346e-08" iyz="0.0" izz="2.0928228446149052e-08"/>
    </inertial>
    <collision>
      <geometry>
        <mesh filename="../meshes/SPL-2B2(W)_s.stl" scale="0.001 0.001 0.001"/>
      </geometry>
    </collision>
  </link>
  <joint name="l_hand_palm_joint" type="fixed">
    <origin rpy="0 0 0" xyz="0 0.006 0"/>
    <parent link="l_hand_base_link"/>
    <child link="l_hand_palm_link"/>
  </joint>
  <link name="l_hand_palm_link">
    <visual>
      <origin rpy="0 0 0" xyz="0 0 0"/>
      <geometry>
        <mesh filename="../meshes/SPD-3B5(W).stl" scale="0.001 0.001 0.001"/>
      </geometry>
    </visual>
    <inertial>
      <origin rpy="0 0 0" xyz="0.0 0.0 0.0"/>
      <mass value="0.001"/>
      <inertia ixx="3.042659030468979e-08" ixy="0.0" ixz="0.0" iyy="1.0920534527495155e-07" iyz="0.0" izz="8.019504918581541e-08"/>
    </inertial>
    <collision>
      <geometry>
        <mesh filename="../meshes/SPD-3B5(W)_s.stl" scale="0.001 0.001 0.001"/>
      </geometry>
    </collision>
  </link>
  <joint name="l_hand_back_joint" type="fixed">
    <origin rpy="0 1.5707963267948966 1.5707963267948966" xyz="-0.0015 0.006 -0.015"/>
    <parent link="l_hand_palm_anchor2_link"/>
    <child link="l_hand_back_link"/>
  </joint>
  <link name="l_hand_back_link">
    <visual>
      <origin rpy="0 0 0" xyz="0 0 0"/>
      <geometry>
        <mesh filename="../meshes/SPD-4B5(W).stl" scale="0.001 0.001 0.001"/>
      </geometry>
    </visual>
    <inertial>
      <origin rpy="0 0 0" xyz="0.0 0.0 0.0"/>
      <mass value="0.001"/>
      <inertia ixx="7.089137125669363e-08" ixy="0.0" ixz="0.0" iyy="1.7794227662393436e-07" iyz="0.0" izz="1.0895405511871226e-07"/>
    </inertial>
    <collision>
      <geometry>
        <mesh filename="../meshes/SPD-4B5(W)_s.stl" scale="0.001 0.001 0.001"/>
      </geometry>
    </collision>
  </link>
  <joint name="l_hand_fingers_ext1_joint" type="fixed">
    <origin rpy="-1.5707963267948966 0 -1.5707963267948966" xyz="0.021 -0.0015 -0.006"/>
    <parent link="l_hand_back_link"/>
    <child link="l_hand_fingers_ext1_link"/>
  </joint>
  <link name="l_hand_fingers_ext1_link">
    <visual>
      <origin rpy="0 0 0" xyz="0 0 0"/>
      <geometry>
        <mesh filename="../meshes/SPL-2B2(W).stl" scale="0.001 0.001 0.001"/>
      </geometry>
    </visual>
    <inertial>
      <origin rpy="0 0 0" xyz="3.975824e-3 0.0 -5.846319e-3"/>
      <mass value="0.001"/>
      <inertia ixx="2.989443002947031e-08" ixy="0.0" ixz="-8.274710338510628e-09" iyy="3.2062954811316346e-08" iyz="0.0" izz="2.0928228446149052e-08"/>
    </inertial>
    <collision>
      <geometry>
        <mesh filename="../meshes/SPL-2B2(W)_s.stl" scale="0.001 0.001 0.001"/>
      </geometry>
    </collision>
  </link>
  <joint name="l_hand_fingers_ext2_joint" type="fixed">
    <origin rpy="-1.5707963267948966 0 -1.5707963267948966" xyz="0.021 -0.0015 0.006"/>
    <parent link="l_hand_back_link"/>
    <child link="l_hand_fingers_ext2_link"/>
  </joint>
  <link name="l_hand_fingers_ext2_link">
    <visual>
      <origin rpy="0 0 0" xyz="0 0 0"/>
      <geometry>
        <mesh filename="../meshes/SPL-2B2(W).stl" scale="0.001 0.001 0.001"/>
      </geometry>
    </visual>
    <inertial>
      <origin rpy="0 0 0" xyz="3.975824e-3 0.0 -5.846319e-3"/>
      <mass value="0.001"/>
      <inertia ixx="2.989443002947031e-08" ixy="0.0" ixz="-8.274710338510628e-09" iyy="3.2062954811316346e-08" iyz="0.0" izz="2.0928228446149052e-08"/>
    </inertial>
    <collision>
      <geometry>
        <mesh filename="../meshes/SPL-2B2(W)_s.stl" scale="0.001 0.001 0.001"/>
      </geometry>
    </collision>
  </link>
  <joint name="l_hand_fingers_int1_joint" type="fixed">
    <origin rpy="3.141592653589793 1.5707963267948966 0" xyz="0.003 0 -0.003"/>
    <parent link="l_hand_fingers_ext1_link"/>
    <child link="l_hand_fingers_int1_link"/>
  </joint>
  <link name="l_hand_fingers_int1_link">
    <visual>
      <origin rpy="0 0 0" xyz="0 0 0"/>
      <geometry>
        <mesh filename="../meshes/SPL-2B2(W).stl" scale="0.001 0.001 0.001"/>
      </geometry>
    </visual>
    <inertial>
      <origin rpy="0 0 0" xyz="3.975824e-3 0.0 -5.846319e-3"/>
      <mass value="0.001"/>
      <inertia ixx="2.989443002947031e-08" ixy="0.0" ixz="-8.274710338510628e-09" iyy="3.2062954811316346e-08" iyz="0.0" izz="2.0928228446149052e-08"/>
    </inertial>
    <collision>
      <geometry>
        <mesh filename="../meshes/SPL-2B2(W)_s.stl" scale="0.001 0.001 0.001"/>
      </geometry>
    </collision>
  </link>
  <joint name="l_hand_fingers_int2_joint" type="fixed">
    <origin rpy="3.141592653589793 1.5707963267948966 0" xyz="0.003 0 -0.003"/>
    <parent link="l_hand_fingers_ext2_link"/>
    <child link="l_hand_fingers_int2_link"/>
  </joint>
  <link name="l_hand_fingers_int2_link">
    <visual>
      <origin rpy="0 0 0" xyz="0 0 0"/>
      <geometry>
        <mesh filename="../meshes/SPL-2B2(W).stl" scale="0.001 0.001 0.001"/>
      </geometry>
    </visual>
    <inertial>
      <origin rpy="0 0 0" xyz="3.975824e-3 0.0 -5.846319e-3"/>
      <mass value="0.001"/>
      <inertia ixx="2.989443002947031e-08" ixy="0.0" ixz="-8.274710338510628e-09" iyy="3.2062954811316346e-08" iyz="0.0" izz="2.0928228446149052e-08"/>
    </inertial>
    <collision>
      <geometry>
        <mesh filename="../meshes/SPL-2B2(W)_s.stl" scale="0.001 0.001 0.001"/>
      </geometry>
    </collision>
  </link>
  <joint name="r_shoulder_servo_joint" type="fixed">
    <origin rpy="3.141592653589793 0 0.0" xyz="0 -0.024 0"/>
    <parent link="r_shoulder_anchor_link"/>
    <child link="r_shoulder_servo_link"/>
  </joint>
  <link name="r_shoulder_servo_link">
    <visual>
      <origin rpy="0 0 0" xyz="0 0 0"/>
      <geometry>
        <mesh filename="../meshes/XL-320D.stl" scale="0.001 0.001 0.001"/>
      </geometry>
    </visual>
    <inertial>
      <origin rpy="0 0 0" xyz="0.0 -6.745858e-3 0.697233e-3"/>
      <mass value="0.02"/>
      <inertia ixx="2.8169401796846998e-06" ixy="0.0" ixz="0.0" iyy="1.8687826796735248e-06" iyz="-9.755271144975289e-08" izz="2.442679644825487e-06"/>
    </inertial>
    <collision>
      <geometry>
        <mesh filename="../meshes/XL-320D.stl" scale="0.001 0.001 0.001"/>
      </geometry>
    </collision>
  </link>
  <joint name="r_shoulder_joint" type="revolute">
    <axis xyz="0 0 1"/>
    <limit effort="0.39" lower="-1.5707963267948966" upper="1.5707963267948966" velocity="11.938052083641214"/>
    <origin rpy="0 0 0" xyz="0 0 0"/>
    <parent link="r_shoulder_servo_link"/>
    <child link="r_shoulder_link"/>
    <!--
      <dynamics damping="${XL320_DAMPING}" />
      -->
  </joint>
  <link name="r_shoulder_link">
    <inertial>
      <mass value="0.0001"/>
      <inertia ixx="1.0e-12" ixy="0.0" ixz="0.0" iyy="1.0e-12" iyz="0.0" izz="1.0e-12"/>
    </inertial>
  </link>
  <transmission name="r_shoulder_tran">
    <type>transmission_interface/SimpleTransmission</type>
    <joint name="r_shoulder_joint">
      <hardwareInterface>EffortJointInterface</hardwareInterface>
    </joint>
    <actuator name="r_shoulder_motor">
      <hardwareInterface>EffortJointInterface</hardwareInterface>
      <mechanicalReduction>1</mechanicalReduction>
    </actuator>
  </transmission>
  <joint name="r_biceps_anchor_joint" type="fixed">
    <origin rpy="1.5707963267948966 0 1.5707963267948966" xyz="-0.012 0 0.033"/>
    <parent link="r_shoulder_link"/>
    <child link="r_biceps_anchor_link"/>
  </joint>
  <link name="r_biceps_anchor_link">
    <visual>
      <origin rpy="0 0 0" xyz="0 0 0"/>
      <geometry>
        <mesh filename="../meshes/DMF-B03(W).stl" scale="0.001 0.001 0.001"/>
      </geometry>
    </visual>
    <inertial>
      <origin rpy="0 0 0" xyz="0.0 -8.846923e-3 7.432426e-3"/>
      <mass value="0.005"/>
      <inertia ixx="5.893486671099843e-07" ixy="0.0" ixz="0.0" iyy="1.3682831066650124e-06" iyz="1.5691252989899708e-07" izz="1.371564647677275e-06"/>
    </inertial>
    <collision>
      <geometry>
        <mesh filename="../meshes/DMF-B03(W)_s.stl" scale="0.001 0.001 0.001"/>
      </geometry>
    </collision>
  </link>
  <joint name="r_biceps_axis_joint" type="fixed">
    <origin rpy="1.5707963267948966 0 -1.5707963267948966" xyz="0 0 0"/>
    <parent link="r_biceps_anchor_link"/>
    <child link="r_biceps_axis_link"/>
  </joint>
  <link name="r_biceps_axis_link">
    <inertial>
      <mass value="0.0001"/>
      <inertia ixx="1.0e-12" ixy="0.0" ixz="0.0" iyy="1.0e-12" iyz="0.0" izz="1.0e-12"/>
    </inertial>
  </link>
  <joint name="r_biceps_joint" type="revolute">
    <axis xyz="0 0 1"/>
    <limit effort="0.39" lower="-1.5707963267948966" upper="1.5707963267948966" velocity="11.938052083641214"/>
    <origin rpy="0 0 -1.5707963267948966" xyz="0 0 0"/>
    <parent link="r_biceps_axis_link"/>
    <child link="r_biceps_link"/>
    <!--
      <dynamics damping="${XL320_DAMPING}" />
      -->
  </joint>
  <link name="r_biceps_link">
    <visual>
      <origin rpy="0 0 0" xyz="0 0 0"/>
      <geometry>
        <mesh filename="../meshes/XL-320D.stl" scale="0.001 0.001 0.001"/>
      </geometry>
    </visual>
    <inertial>
      <origin rpy="0 0 0" xyz="0.0 -6.745858e-3 0.697233e-3"/>
      <mass value="0.02"/>
      <inertia ixx="2.8169401796846998e-06" ixy="0.0" ixz="0.0" iyy="1.8687826796735248e-06" iyz="-9.755271144975289e-08" izz="2.442679644825487e-06"/>
    </inertial>
    <collision>
      <geometry>
        <mesh filename="../meshes/XL-320D.stl" scale="0.001 0.001 0.001"/>
      </geometry>
    </collision>
  </link>
  <transmission name="r_biceps_tran">
    <type>transmission_interface/SimpleTransmission</type>
    <joint name="r_biceps_joint">
      <hardwareInterface>EffortJointInterface</hardwareInterface>
    </joint>
    <actuator name="r_biceps_motor">
      <hardwareInterface>EffortJointInterface</hardwareInterface>
      <mechanicalReduction>1</mechanicalReduction>
    </actuator>
  </transmission>
  <joint name="r_biceps_spo_joint" type="fixed">
    <origin rpy="1.5707963267948966 0 0" xyz="0 0 -0.015"/>
    <parent link="r_biceps_link"/>
    <child link="r_biceps_spo_link"/>
  </joint>
  <link name="r_biceps_spo_link">
    <visual>
      <origin rpy="0 0 0" xyz="0 0 0"/>
      <geometry>
        <mesh filename="../meshes/SPO-5(GR).stl" scale="0.001 0.001 0.001"/>
      </geometry>
    </visual>
    <inertial>
      <origin rpy="0 0 0" xyz="-0.004686e-3 1.501381e-3 -0.004686e-3"/>
      <mass value="0.001"/>
      <inertia ixx="1.511699541429177e-08" ixy="-3.7907332468947e-12" ixz="1.2866184946294198e-11" iyy="2.9213253615331356e-08" iyz="-3.7907092213548e-12" izz="1.511699541429177e-08"/>
    </inertial>
    <collision>
      <geometry>
        <mesh filename="../meshes/SPO-5(GR)_s.stl" scale="0.001 0.001 0.001"/>
      </geometry>
    </collision>
  </link>
  <joint name="r_upper_arm_joint" type="fixed">
    <origin rpy="3.141592653589793 1.5707963267948966 0" xyz="0 -0.045 0"/>
    <parent link="r_biceps_link"/>
    <child link="r_upper_arm_link"/>
  </joint>
  <link name="r_upper_arm_link">
    <visual>
      <origin rpy="0 0 0" xyz="0 0 0"/>
      <geometry>
        <mesh filename="../meshes/DMF-B04(W).stl" scale="0.001 0.001 0.001"/>
      </geometry>
    </visual>
    <inertial>
      <origin rpy="0 0 0" xyz="0.0 -16.650940e-3 3.893445e-3"/>
      <mass value="0.007"/>
      <inertia ixx="1.4844145053407249e-06" ixy="0.0" ixz="0.0" iyy="1.5912567135270748e-06" iyz="3.5247996037499997e-07" izz="2.3466465586526997e-06"/>
    </inertial>
    <collision>
      <geometry>
        <mesh filename="../meshes/DMF-B04(W)_s.stl" scale="0.001 0.001 0.001"/>
      </geometry>
    </collision>
  </link>
  <joint name="r_elbow_axis_joint" type="fixed">
    <origin rpy="3.141592653589793 1.5707963267948966 0" xyz="0 0 0"/>
    <parent link="r_upper_arm_link"/>
    <child link="r_elbow_axis_link"/>
  </joint>
  <link name="r_elbow_axis_link">
    <inertial>
      <mass value="0.0001"/>
      <inertia ixx="1.0e-12" ixy="0.0" ixz="0.0" iyy="1.0e-12" iyz="0.0" izz="1.0e-12"/>
    </inertial>
  </link>
  <joint name="r_elbow_joint" type="revolute">
    <axis xyz="0 0 1"/>
    <limit effort="0.39" lower="-1.5707963267948966" upper="1.5707963267948966" velocity="11.938052083641214"/>
    <origin rpy="0 0 0" xyz="0 0 0"/>
    <parent link="r_elbow_axis_link"/>
    <child link="r_elbow_link"/>
    <!--
      <dynamics damping="${XL320_DAMPING}" />
      -->
  </joint>
  <link name="r_elbow_link">
    <visual>
      <origin rpy="0 0 0" xyz="0 0 0"/>
      <geometry>
        <mesh filename="../meshes/XL-320D.stl" scale="0.001 0.001 0.001"/>
      </geometry>
    </visual>
    <inertial>
      <origin rpy="0 0 0" xyz="0.0 -6.745858e-3 0.697233e-3"/>
      <mass value="0.02"/>
      <inertia ixx="2.8169401796846998e-06" ixy="0.0" ixz="0.0" iyy="1.8687826796735248e-06" iyz="-9.755271144975289e-08" izz="2.442679644825487e-06"/>
    </inertial>
    <collision>
      <geometry>
        <mesh filename="../meshes/XL-320D.stl" scale="0.001 0.001 0.001"/>
      </geometry>
    </collision>
  </link>
  <transmission name="r_elbow_tran">
    <type>transmission_interface/SimpleTransmission</type>
    <joint name="r_elbow_joint">
      <hardwareInterface>EffortJointInterface</hardwareInterface>
    </joint>
    <actuator name="r_elbow_motor">
      <hardwareInterface>EffortJointInterface</hardwareInterface>
      <mechanicalReduction>1</mechanicalReduction>
    </actuator>
  </transmission>
  <joint name="r_elbow_spo_joint" type="fixed">
    <origin rpy="1.5707963267948966 0 0" xyz="0 0 -0.015"/>
    <parent link="r_elbow_link"/>
    <child link="r_elbow_spo_link"/>
  </joint>
  <link name="r_elbow_spo_link">
    <visual>
      <origin rpy="0 0 0" xyz="0 0 0"/>
      <geometry>
        <mesh filename="../meshes/SPO-5(GR).stl" scale="0.001 0.001 0.001"/>
      </geometry>
    </visual>
    <inertial>
      <origin rpy="0 0 0" xyz="-0.004686e-3 1.501381e-3 -0.004686e-3"/>
      <mass value="0.001"/>
      <inertia ixx="1.511699541429177e-08" ixy="-3.7907332468947e-12" ixz="1.2866184946294198e-11" iyy="2.9213253615331356e-08" iyz="-3.7907092213548e-12" izz="1.511699541429177e-08"/>
    </inertial>
    <collision>
      <geometry>
        <mesh filename="../meshes/SPO-5(GR)_s.stl" scale="0.001 0.001 0.001"/>
      </geometry>
    </collision>
  </link>
  <joint name="r_lower_arm_joint" type="fixed">
    <origin rpy="0 3.141592653589793 3.141592653589793" xyz="0 -0.024 0"/>
    <parent link="r_elbow_link"/>
    <child link="r_lower_arm_link"/>
  </joint>
  <link name="r_lower_arm_link">
    <visual>
      <origin rpy="0 0 0" xyz="0 0 0"/>
      <geometry>
        <mesh filename="../meshes/SPU-5(W).stl" scale="0.001 0.001 0.001"/>
      </geometry>
    </visual>
    <inertial>
      <origin rpy="0 0 0" xyz="0.0 1.31172e-3 0.0"/>
      <mass value="0.001"/>
      <inertia ixx="2.7160998812739677e-08" ixy="0.0" ixz="0.0" iyy="5.2595636134718856e-08" iyz="0.0" izz="2.8058676756667802e-08"/>
    </inertial>
    <collision>
      <geometry>
        <mesh filename="../meshes/SPU-5(W)_s.stl" scale="0.001 0.001 0.001"/>
      </geometry>
    </collision>
  </link>
  <joint name="r_wrist_anchor_joint" type="fixed">
    <origin rpy="0 0 0" xyz="0 0.0045 0"/>
    <parent link="r_lower_arm_link"/>
    <child link="r_wrist_anchor_link"/>
  </joint>
  <link name="r_wrist_anchor_link">
    <visual>
      <origin rpy="0 0 0" xyz="0 0 0"/>
      <geometry>
        <mesh filename="../meshes/SPD-3B3(W).stl" scale="0.001 0.001 0.001"/>
      </geometry>
    </visual>
    <inertial>
      <origin rpy="0 0 0" xyz="0.0 0.0 0.0"/>
      <mass value="0.001"/>
      <inertia ixx="1.7427879176605523e-08" ixy="0.0" ixz="0.0" iyy="3.4023619651757087e-08" iyz="0.0" izz="1.7427879176605523e-08"/>
    </inertial>
    <collision>
      <geometry>
        <mesh filename="../meshes/SPD-3B3(W)_s.stl" scale="0.001 0.001 0.001"/>
      </geometry>
    </collision>
  </link>
  <joint name="r_hand_wrist1_joint" type="fixed">
    <origin rpy="0 0 0" xyz="0 0.0015 0"/>
    <parent link="r_wrist_anchor_link"/>
    <child link="r_hand_wrist1_link"/>
  </joint>
  <link name="r_hand_wrist1_link">
    <visual>
      <origin rpy="0 0 0" xyz="0 0 0"/>
      <geometry>
        <mesh filename="../meshes/SPO-5(GR).stl" scale="0.001 0.001 0.001"/>
      </geometry>
    </visual>
    <inertial>
      <origin rpy="0 0 0" xyz="-0.004686e-3 1.501381e-3 -0.004686e-3"/>
      <mass value="0.001"/>
      <inertia ixx="1.511699541429177e-08" ixy="-3.7907332468947e-12" ixz="1.2866184946294198e-11" iyy="2.9213253615331356e-08" iyz="-3.7907092213548e-12" izz="1.511699541429177e-08"/>
    </inertial>
    <collision>
      <geometry>
        <mesh filename="../meshes/SPO-5(GR)_s.stl" scale="0.001 0.001 0.001"/>
      </geometry>
    </collision>
  </link>
  <joint name="r_hand_wrist2_joint" type="fixed">
    <origin rpy="0 0 0" xyz="0 0.003 0"/>
    <parent link="r_hand_wrist1_link"/>
    <child link="r_hand_wrist2_link"/>
  </joint>
  <link name="r_hand_wrist2_link">
    <visual>
      <origin rpy="0 0 0" xyz="0 0 0"/>
      <geometry>
        <mesh filename="../meshes/SPO-5(GR).stl" scale="0.001 0.001 0.001"/>
      </geometry>
    </visual>
    <inertial>
      <origin rpy="0 0 0" xyz="-0.004686e-3 1.501381e-3 -0.004686e-3"/>
      <mass value="0.001"/>
      <inertia ixx="1.511699541429177e-08" ixy="-3.7907332468947e-12" ixz="1.2866184946294198e-11" iyy="2.9213253615331356e-08" iyz="-3.7907092213548e-12" izz="1.511699541429177e-08"/>
    </inertial>
    <collision>
      <geometry>
        <mesh filename="../meshes/SPO-5(GR)_s.stl" scale="0.001 0.001 0.001"/>
      </geometry>
    </collision>
  </link>
  <joint name="r_hand_base_joint" type="fixed">
    <origin rpy="0 1.5707963267948966 0" xyz="0 0.0045 0"/>
    <parent link="r_hand_wrist2_link"/>
    <child link="r_hand_base_link"/>
  </joint>
  <link name="r_hand_base_link">
    <visual>
      <origin rpy="0 0 0" xyz="0 0 0"/>
      <geometry>
        <mesh filename="../meshes/SPD-3B5(W).stl" scale="0.001 0.001 0.001"/>
      </geometry>
    </visual>
    <inertial>
      <origin rpy="0 0 0" xyz="0.0 0.0 0.0"/>
      <mass value="0.001"/>
      <inertia ixx="3.042659030468979e-08" ixy="0.0" ixz="0.0" iyy="1.0920534527495155e-07" iyz="0.0" izz="8.019504918581541e-08"/>
    </inertial>
    <collision>
      <geometry>
        <mesh filename="../meshes/SPD-3B5(W)_s.stl" scale="0.001 0.001 0.001"/>
      </geometry>
    </collision>
  </link>
  <joint name="r_hand_thumb_joint" type="fixed">
    <origin rpy="1.5707963267948966 3.141592653589793 0" xyz="0.018 0.0015 0.009"/>
    <parent link="r_hand_base_link"/>
    <child link="r_hand_thumb_link"/>
  </joint>
  <link name="r_hand_thumb_link">
    <visual>
      <origin rpy="0 0 0" xyz="0 0 0"/>
      <geometry>
        <mesh filename="../meshes/SPL-2B2(W).stl" scale="0.001 0.001 0.001"/>
      </geometry>
    </visual>
    <inertial>
      <origin rpy="0 0 0" xyz="3.975824e-3 0.0 -5.846319e-3"/>
      <mass value="0.001"/>
      <inertia ixx="2.989443002947031e-08" ixy="0.0" ixz="-8.274710338510628e-09" iyy="3.2062954811316346e-08" iyz="0.0" izz="2.0928228446149052e-08"/>
    </inertial>
    <collision>
      <geometry>
        <mesh filename="../meshes/SPL-2B2(W)_s.stl" scale="0.001 0.001 0.001"/>
      </geometry>
    </collision>
  </link>
  <joint name="r_hand_palm_anchor1_joint" type="fixed">
    <origin rpy="1.5707963267948966 -1.5707963267948966 0" xyz="0.003 0.0015 -0.012"/>
    <parent link="r_hand_base_link"/>
    <child link="r_hand_palm_anchor1_link"/>
  </joint>
  <link name="r_hand_palm_anchor1_link">
    <visual>
      <origin rpy="0 0 0" xyz="0 0 0"/>
      <geometry>
        <mesh filename="../meshes/SPL-2B2(W).stl" scale="0.001 0.001 0.001"/>
      </geometry>
    </visual>
    <inertial>
      <origin rpy="0 0 0" xyz="3.975824e-3 0.0 -5.846319e-3"/>
      <mass value="0.001"/>
      <inertia ixx="2.989443002947031e-08" ixy="0.0" ixz="-8.274710338510628e-09" iyy="3.2062954811316346e-08" iyz="0.0" izz="2.0928228446149052e-08"/>
    </inertial>
    <collision>
      <geometry>
        <mesh filename="../meshes/SPL-2B2(W)_s.stl" scale="0.001 0.001 0.001"/>
      </geometry>
    </collision>
  </link>
  <joint name="r_hand_palm_anchor2_joint" type="fixed">
    <origin rpy="1.5707963267948966 -1.5707963267948966 0" xyz="-0.009 0.0015 -0.012"/>
    <parent link="r_hand_base_link"/>
    <child link="r_hand_palm_anchor2_link"/>
  </joint>
  <link name="r_hand_palm_anchor2_link">
    <visual>
      <origin rpy="0 0 0" xyz="0 0 0"/>
      <geometry>
        <mesh filename="../meshes/SPL-2B2(W).stl" scale="0.001 0.001 0.001"/>
      </geometry>
    </visual>
    <inertial>
      <origin rpy="0 0 0" xyz="3.975824e-3 0.0 -5.846319e-3"/>
      <mass value="0.001"/>
      <inertia ixx="2.989443002947031e-08" ixy="0.0" ixz="-8.274710338510628e-09" iyy="3.2062954811316346e-08" iyz="0.0" izz="2.0928228446149052e-08"/>
    </inertial>
    <collision>
      <geometry>
        <mesh filename="../meshes/SPL-2B2(W)_s.stl" scale="0.001 0.001 0.001"/>
      </geometry>
    </collision>
  </link>
  <joint name="r_hand_palm_joint" type="fixed">
    <origin rpy="0 0 0" xyz="0 0.006 0"/>
    <parent link="r_hand_base_link"/>
    <child link="r_hand_palm_link"/>
  </joint>
  <link name="r_hand_palm_link">
    <visual>
      <origin rpy="0 0 0" xyz="0 0 0"/>
      <geometry>
        <mesh filename="../meshes/SPD-3B5(W).stl" scale="0.001 0.001 0.001"/>
      </geometry>
    </visual>
    <inertial>
      <origin rpy="0 0 0" xyz="0.0 0.0 0.0"/>
      <mass value="0.001"/>
      <inertia ixx="3.042659030468979e-08" ixy="0.0" ixz="0.0" iyy="1.0920534527495155e-07" iyz="0.0" izz="8.019504918581541e-08"/>
    </inertial>
    <collision>
      <geometry>
        <mesh filename="../meshes/SPD-3B5(W)_s.stl" scale="0.001 0.001 0.001"/>
      </geometry>
    </collision>
  </link>
  <joint name="r_hand_back_joint" type="fixed">
    <origin rpy="0 1.5707963267948966 1.5707963267948966" xyz="-0.0015 -0.006 -0.015"/>
    <parent link="r_hand_palm_anchor2_link"/>
    <child link="r_hand_back_link"/>
  </joint>
  <link name="r_hand_back_link">
    <visual>
      <origin rpy="0 0 0" xyz="0 0 0"/>
      <geometry>
        <mesh filename="../meshes/SPD-4B5(W).stl" scale="0.001 0.001 0.001"/>
      </geometry>
    </visual>
    <inertial>
      <origin rpy="0 0 0" xyz="0.0 0.0 0.0"/>
      <mass value="0.001"/>
      <inertia ixx="7.089137125669363e-08" ixy="0.0" ixz="0.0" iyy="1.7794227662393436e-07" iyz="0.0" izz="1.0895405511871226e-07"/>
    </inertial>
    <collision>
      <geometry>
        <mesh filename="../meshes/SPD-4B5(W)_s.stl" scale="0.001 0.001 0.001"/>
      </geometry>
    </collision>
  </link>
  <joint name="r_hand_fingers_ext1_joint" type="fixed">
    <origin rpy="-1.5707963267948966 0 -1.5707963267948966" xyz="0.021 -0.0015 -0.006"/>
    <parent link="r_hand_back_link"/>
    <child link="r_hand_fingers_ext1_link"/>
  </joint>
  <link name="r_hand_fingers_ext1_link">
    <visual>
      <origin rpy="0 0 0" xyz="0 0 0"/>
      <geometry>
        <mesh filename="../meshes/SPL-2B2(W).stl" scale="0.001 0.001 0.001"/>
      </geometry>
    </visual>
    <inertial>
      <origin rpy="0 0 0" xyz="3.975824e-3 0.0 -5.846319e-3"/>
      <mass value="0.001"/>
      <inertia ixx="2.989443002947031e-08" ixy="0.0" ixz="-8.274710338510628e-09" iyy="3.2062954811316346e-08" iyz="0.0" izz="2.0928228446149052e-08"/>
    </inertial>
    <collision>
      <geometry>
        <mesh filename="../meshes/SPL-2B2(W)_s.stl" scale="0.001 0.001 0.001"/>
      </geometry>
    </collision>
  </link>
  <joint name="r_hand_fingers_ext2_joint" type="fixed">
    <origin rpy="-1.5707963267948966 0 -1.5707963267948966" xyz="0.021 -0.0015 0.006"/>
    <parent link="r_hand_back_link"/>
    <child link="r_hand_fingers_ext2_link"/>
  </joint>
  <link name="r_hand_fingers_ext2_link">
    <visual>
      <origin rpy="0 0 0" xyz="0 0 0"/>
      <geometry>
        <mesh filename="../meshes/SPL-2B2(W).stl" scale="0.001 0.001 0.001"/>
      </geometry>
    </visual>
    <inertial>
      <origin rpy="0 0 0" xyz="3.975824e-3 0.0 -5.846319e-3"/>
      <mass value="0.001"/>
      <inertia ixx="2.989443002947031e-08" ixy="0.0" ixz="-8.274710338510628e-09" iyy="3.2062954811316346e-08" iyz="0.0" izz="2.0928228446149052e-08"/>
    </inertial>
    <collision>
      <geometry>
        <mesh filename="../meshes/SPL-2B2(W)_s.stl" scale="0.001 0.001 0.001"/>
      </geometry>
    </collision>
  </link>
  <joint name="r_hand_fingers_int1_joint" type="fixed">
    <origin rpy="3.141592653589793 1.5707963267948966 0" xyz="0.003 0 -0.003"/>
    <parent link="r_hand_fingers_ext1_link"/>
    <child link="r_hand_fingers_int1_link"/>
  </joint>
  <link name="r_hand_fingers_int1_link">
    <visual>
      <origin rpy="0 0 0" xyz="0 0 0"/>
      <geometry>
        <mesh filename="../meshes/SPL-2B2(W).stl" scale="0.001 0.001 0.001"/>
      </geometry>
    </visual>
    <inertial>
      <origin rpy="0 0 0" xyz="3.975824e-3 0.0 -5.846319e-3"/>
      <mass value="0.001"/>
      <inertia ixx="2.989443002947031e-08" ixy="0.0" ixz="-8.274710338510628e-09" iyy="3.2062954811316346e-08" iyz="0.0" izz="2.0928228446149052e-08"/>
    </inertial>
    <collision>
      <geometry>
        <mesh filename="../meshes/SPL-2B2(W)_s.stl" scale="0.001 0.001 0.001"/>
      </geometry>
    </collision>
  </link>
  <joint name="r_hand_fingers_int2_joint" type="fixed">
    <origin rpy="3.141592653589793 1.5707963267948966 0" xyz="0.003 0 -0.003"/>
    <parent link="r_hand_fingers_ext2_link"/>
    <child link="r_hand_fingers_int2_link"/>
  </joint>
  <link name="r_hand_fingers_int2_link">
    <visual>
      <origin rpy="0 0 0" xyz="0 0 0"/>
      <geometry>
        <mesh filename="../meshes/SPL-2B2(W).stl" scale="0.001 0.001 0.001"/>
      </geometry>
    </visual>
    <inertial>
      <origin rpy="0 0 0" xyz="3.975824e-3 0.0 -5.846319e-3"/>
      <mass value="0.001"/>
      <inertia ixx="2.989443002947031e-08" ixy="0.0" ixz="-8.274710338510628e-09" iyy="3.2062954811316346e-08" iyz="0.0" izz="2.0928228446149052e-08"/>
    </inertial>
    <collision>
      <geometry>
        <mesh filename="../meshes/SPL-2B2(W)_s.stl" scale="0.001 0.001 0.001"/>
      </geometry>
    </collision>
  </link>
  <joint name="l_hip_servo_joint" type="fixed">
    <origin rpy="0 0 3.141592653589793" xyz="0 -0.024 0"/>
    <parent link="l_hip_anchor_link"/>
    <child link="l_hip_servo_link"/>
  </joint>
  <link name="l_hip_servo_link">
    <visual>
      <origin rpy="0 0 0" xyz="0 0 0"/>
      <geometry>
        <mesh filename="../meshes/XL-320D.stl" scale="0.001 0.001 0.001"/>
      </geometry>
    </visual>
    <inertial>
      <origin rpy="0 0 0" xyz="0.0 -6.745858e-3 0.697233e-3"/>
      <mass value="0.02"/>
      <inertia ixx="2.8169401796846998e-06" ixy="0.0" ixz="0.0" iyy="1.8687826796735248e-06" iyz="-9.755271144975289e-08" izz="2.442679644825487e-06"/>
    </inertial>
    <collision>
      <geometry>
        <mesh filename="../meshes/XL-320D.stl" scale="0.001 0.001 0.001"/>
      </geometry>
    </collision>
  </link>
  <joint name="l_hip_joint" type="revolute">
    <axis xyz="0 0 1"/>
    <limit effort="0.39" lower="-1.5707963267948966" upper="1.5707963267948966" velocity="11.938052083641214"/>
    <origin rpy="0 0 0" xyz="0 0 0"/>
    <parent link="l_hip_servo_link"/>
    <child link="l_hip_link"/>
    <!--
      <dynamics damping="${XL320_DAMPING}" />
      -->
  </joint>
  <link name="l_hip_link">
    <inertial>
      <mass value="0.0001"/>
      <inertia ixx="1.0e-12" ixy="0.0" ixz="0.0" iyy="1.0e-12" iyz="0.0" izz="1.0e-12"/>
    </inertial>
  </link>
  <transmission name="l_hip_tran">
    <type>transmission_interface/SimpleTransmission</type>
    <joint name="l_hip_joint">
      <hardwareInterface>EffortJointInterface</hardwareInterface>
    </joint>
    <actuator name="l_hip_motor">
      <hardwareInterface>EffortJointInterface</hardwareInterface>
      <mechanicalReduction>1</mechanicalReduction>
    </actuator>
  </transmission>
  <joint name="l_groin_joint" type="fixed">
    <origin rpy="-1.5707963267948966 0 -1.5707963267948966" xyz="0 0 0.0165"/>
    <parent link="l_hip_link"/>
    <child link="l_groin_link"/>
  </joint>
  <link name="l_groin_link">
    <visual>
      <origin rpy="0 0 0" xyz="0 0 0"/>
      <geometry>
        <mesh filename="../meshes/SPD-7V4(W).stl" scale="0.001 0.001 0.001"/>
      </geometry> 
    </visual>
    <inertial>
      <origin rpy="0 0 0" xyz="0.0 -0.147827e-3 0.0"/>
      <mass value="0.001"/>
      <inertia ixx="3.840285715433655e-08" ixy="0.0" ixz="0.0" iyy="1.2485384525184085e-07" iyz="0.0" izz="8.815456632304686e-08"/>
    </inertial>
    <collision>
      <geometry>
        <mesh filename="../meshes/SPD-7V4(W)_s.stl" scale="0.001 0.001 0.001"/>
      </geometry>
    </collision>
  </link>
  <joint name="l_thigh_anchor_joint" type="fixed">
    <origin rpy="0 0 0" xyz="0 -0.003 0"/>
    <parent link="l_groin_link"/>
    <child link="l_thigh_anchor_link"/>
  </joint>
  <link name="l_thigh_anchor_link">
    <visual>
      <origin rpy="0 0 0" xyz="0 0 0"/>
      <geometry>
        <mesh filename="../meshes/SPD-3B5(W).stl" scale="0.001 0.001 0.001"/>
      </geometry>
    </visual>
    <inertial>
      <origin rpy="0 0 0" xyz="0.0 0.0 0.0"/>
      <mass value="0.001"/>
      <inertia ixx="3.042659030468979e-08" ixy="0.0" ixz="0.0" iyy="1.0920534527495155e-07" iyz="0.0" izz="8.019504918581541e-08"/>
    </inertial>
    <collision>
      <geometry>
        <mesh filename="../meshes/SPD-3B5(W)_s.stl" scale="0.001 0.001 0.001"/>
      </geometry>
    </collision>
  </link>
  <joint name="l_thigh_servo_joint" type="fixed">
    <origin rpy="0.0 0 1.5707963267948966" xyz="-0.006 -0.0135 0"/>
    <parent link="l_thigh_anchor_link"/>
    <child link="l_thigh_servo_link"/>
  </joint>
  <link name="l_thigh_servo_link">
    <visual>
      <origin rpy="0 0 0" xyz="0 0 0"/>
      <geometry>
        <mesh filename="../meshes/XL-320D.stl" scale="0.001 0.001 0.001"/>
      </geometry>
    </visual>
    <inertial>
      <origin rpy="0 0 0" xyz="0.0 -6.745858e-3 0.697233e-3"/>
      <mass value="0.02"/>
      <inertia ixx="2.8169401796846998e-06" ixy="0.0" ixz="0.0" iyy="1.8687826796735248e-06" iyz="-9.755271144975289e-08" izz="2.442679644825487e-06"/>
    </inertial>
    <collision>
      <geometry>
        <mesh filename="../meshes/XL-320D.stl" scale="0.001 0.001 0.001"/>
      </geometry>
    </collision>
  </link>
  <joint name="l_thigh_joint" type="revolute">
    <axis xyz="0 0 -1"/>
    <limit effort="0.39" lower="-1.5707963267948966" upper="1.5707963267948966" velocity="11.938052083641214"/>
    <origin rpy="0 0 0" xyz="0 0 0"/>
    <parent link="l_thigh_servo_link"/>
    <child link="l_thigh_link"/>
    <!--
      <dynamics damping="${XL320_DAMPING}" />
      -->
  </joint>
  <link name="l_thigh_link">
    <inertial>
      <mass value="0.0001"/>
      <inertia ixx="1.0e-12" ixy="0.0" ixz="0.0" iyy="1.0e-12" iyz="0.0" izz="1.0e-12"/>
    </inertial>
  </link>
  <transmission name="l_thigh_tran">
    <type>transmission_interface/SimpleTransmission</type>
    <joint name="l_thigh_joint">
      <hardwareInterface>EffortJointInterface</hardwareInterface>
    </joint>
    <actuator name="l_thigh_motor">
      <hardwareInterface>EffortJointInterface</hardwareInterface>
      <mechanicalReduction>1</mechanicalReduction>
    </actuator>
  </transmission>
  <joint name="l_thigh_spo_joint" type="fixed">
    <origin rpy="1.5707963267948966 0 0" xyz="0 0 -0.015"/>
    <parent link="l_thigh_link"/>
    <child link="l_thigh_spo_link"/>
  </joint>
  <link name="l_thigh_spo_link">
    <visual>
      <origin rpy="0 0 0" xyz="0 0 0"/>
      <geometry>
        <mesh filename="../meshes/SPO-5(GR).stl" scale="0.001 0.001 0.001"/>
      </geometry>
    </visual>
    <inertial>
      <origin rpy="0 0 0" xyz="-0.004686e-3 1.501381e-3 -0.004686e-3"/>
      <mass value="0.001"/>
      <inertia ixx="1.511699541429177e-08" ixy="-3.7907332468947e-12" ixz="1.2866184946294198e-11" iyy="2.9213253615331356e-08" iyz="-3.7907092213548e-12" izz="1.511699541429177e-08"/>
    </inertial>
    <collision>
      <geometry>
        <mesh filename="../meshes/SPO-5(GR)_s.stl" scale="0.001 0.001 0.001"/>
      </geometry>
    </collision>
  </link>
  <joint name="l_thigh_top_joint" type="fixed">
    <origin rpy="0 0 3.141592653589793" xyz="0 -0.024 0"/>
    <parent link="l_thigh_servo_link"/>
    <child link="l_thigh_top_link"/>
  </joint>
  <link name="l_thigh_top_link">
    <visual>
      <origin rpy="0 0 0" xyz="0 0 0"/>
      <geometry>
        <mesh filename="../meshes/SPU-5(W).stl" scale="0.001 0.001 0.001"/>
      </geometry>
    </visual>
    <inertial>
      <origin rpy="0 0 0" xyz="0.0 1.31172e-3 0.0"/>
      <mass value="0.001"/>
      <inertia ixx="2.7160998812739677e-08" ixy="0.0" ixz="0.0" iyy="5.2595636134718856e-08" iyz="0.0" izz="2.8058676756667802e-08"/>
    </inertial>
    <collision>
      <geometry>
        <mesh filename="../meshes/SPU-5(W)_s.stl" scale="0.001 0.001 0.001"/>
      </geometry>
    </collision>
  </link>
  <joint name="l_upper_leg_joint" type="fixed">
    <origin rpy="0 1.5707963267948966 3.141592653589793" xyz="0 0 0"/>
    <parent link="l_thigh_link"/>
    <child link="l_upper_leg_link"/>
  </joint>
  <link name="l_upper_leg_link">
    <visual>
      <origin rpy="0 0 0" xyz="0 0 0"/>
      <geometry>
        <mesh filename="../meshes/DMF-B04(W).stl" scale="0.001 0.001 0.001"/>
      </geometry>
    </visual>
    <inertial>
      <origin rpy="0 0 0" xyz="0.0 -16.650940e-3 3.893445e-3"/>
      <mass value="0.007"/>
      <inertia ixx="1.4844145053407249e-06" ixy="0.0" ixz="0.0" iyy="1.5912567135270748e-06" iyz="3.5247996037499997e-07" izz="2.3466465586526997e-06"/>
    </inertial>
    <collision>
      <geometry>
        <mesh filename="../meshes/DMF-B04(W)_s.stl" scale="0.001 0.001 0.001"/>
      </geometry>
    </collision>
  </link>
  <joint name="l_knee_servo_joint" type="fixed">
    <origin rpy="3.141592653589793 1.5707963267948966 0" xyz="0 -0.045 0"/>
    <parent link="l_upper_leg_link"/>
    <child link="l_knee_servo_link"/>
  </joint>
  <link name="l_knee_servo_link">
    <visual>
      <origin rpy="0 0 0" xyz="0 0 0"/>
      <geometry>
        <mesh filename="../meshes/XL-320D.stl" scale="0.001 0.001 0.001"/>
      </geometry>
    </visual>
    <inertial>
      <origin rpy="0 0 0" xyz="0.0 -6.745858e-3 0.697233e-3"/>
      <mass value="0.02"/>
      <inertia ixx="2.8169401796846998e-06" ixy="0.0" ixz="0.0" iyy="1.8687826796735248e-06" iyz="-9.755271144975289e-08" izz="2.442679644825487e-06"/>
    </inertial>
    <collision>
      <geometry>
        <mesh filename="../meshes/XL-320D.stl" scale="0.001 0.001 0.001"/>
      </geometry>
    </collision>
  </link>
  <joint name="l_knee_joint" type="revolute">
    <axis xyz="0 0 -1"/>
    <limit effort="0.39" lower="-1.5707963267948966" upper="1.5707963267948966" velocity="11.938052083641214"/>
    <origin rpy="0 0 0" xyz="0 0 0"/>
    <parent link="l_knee_servo_link"/>
    <child link="l_knee_link"/>
    <!--
      <dynamics damping="${XL320_DAMPING}" />
      -->
  </joint>
  <link name="l_knee_link">
    <inertial>
      <mass value="0.0001"/>
      <inertia ixx="1.0e-12" ixy="0.0" ixz="0.0" iyy="1.0e-12" iyz="0.0" izz="1.0e-12"/>
    </inertial>
  </link>
  <transmission name="l_knee_tran">
    <type>transmission_interface/SimpleTransmission</type>
    <joint name="l_knee_joint">
      <hardwareInterface>EffortJointInterface</hardwareInterface>
    </joint>
    <actuator name="l_knee_motor">
      <hardwareInterface>EffortJointInterface</hardwareInterface>
      <mechanicalReduction>1</mechanicalReduction>
    </actuator>
  </transmission>
  <joint name="l_knee_spo_joint" type="fixed">
    <origin rpy="1.5707963267948966 0 0" xyz="0 0 -0.015"/>
    <parent link="l_knee_link"/>
    <child link="l_knee_spo_link"/>
  </joint>
  <link name="l_knee_spo_link">
    <visual>
      <origin rpy="0 0 0" xyz="0 0 0"/>
      <geometry>
        <mesh filename="../meshes/SPO-5(GR).stl" scale="0.001 0.001 0.001"/>
      </geometry>
    </visual>
    <inertial>
      <origin rpy="0 0 0" xyz="-0.004686e-3 1.501381e-3 -0.004686e-3"/>
      <mass value="0.001"/>
      <inertia ixx="1.511699541429177e-08" ixy="-3.7907332468947e-12" ixz="1.2866184946294198e-11" iyy="2.9213253615331356e-08" iyz="-3.7907092213548e-12" izz="1.511699541429177e-08"/>
    </inertial>
    <collision>
      <geometry>
        <mesh filename="../meshes/SPO-5(GR)_s.stl" scale="0.001 0.001 0.001"/>
      </geometry>
    </collision>
  </link>
  <joint name="l_lower_leg_joint" type="fixed">
    <origin rpy="-1.5707963267948966 1.5707963267948966 0" xyz="0 0 0"/>
    <parent link="l_knee_link"/>
    <child link="l_lower_leg_link"/>
  </joint>
  <link name="l_lower_leg_link">
    <visual>
      <origin rpy="0 0 0" xyz="0 0 0"/>
      <geometry>
        <mesh filename="../meshes/DMF-B05(W).stl" scale="0.001 0.001 0.001"/>
      </geometry>
    </visual>
    <inertial>
      <origin rpy="0 0 0" xyz="0.000002e-3 6.883461e-3 17.899050e-3"/>
      <mass value="0.011"/>
      <inertia ixx="4.3095862775709e-06" ixy="0.0" ixz="0.0" iyy="5.85866900093325e-06" iyz="5.592906618791718e-07" izz="3.6828383407100998e-06"/>
    </inertial>
    <collision>
      <geometry>
        <mesh filename="../meshes/DMF-B05(W)_s.stl" scale="0.001 0.001 0.001"/>
      </geometry>
    </collision>
  </link>
  <joint name="l_ankle_axis_joint" type="fixed">
    <origin rpy="1.5707963267948966 0 -1.5707963267948966" xyz="0 0 0.042"/>
    <parent link="l_lower_leg_link"/>
    <child link="l_ankle_axis_link"/>
  </joint>
  <link name="l_ankle_axis_link">
    <inertial>
      <mass value="0.0001"/>
      <inertia ixx="1.0e-12" ixy="0.0" ixz="0.0" iyy="1.0e-12" iyz="0.0" izz="1.0e-12"/>
    </inertial>
  </link>
  <joint name="l_ankle_joint" type="revolute">
    <axis xyz="0 0 -1"/>
    <limit effort="0.39" lower="-1.5707963267948966" upper="1.5707963267948966" velocity="11.938052083641214"/>
    <origin rpy="0 0 0" xyz="0 0 0"/>
    <parent link="l_ankle_axis_link"/>
    <child link="l_ankle_link"/>
    <!--
      <dynamics damping="${XL320_DAMPING}" />
      -->
  </joint>
  <link name="l_ankle_link">
    <visual>
      <origin rpy="0 0 0" xyz="0 0 0"/>
      <geometry>
        <mesh filename="../meshes/XL-320D.stl" scale="0.001 0.001 0.001"/>
      </geometry>
    </visual>
    <inertial>
      <origin rpy="0 0 0" xyz="0.0 -6.745858e-3 0.697233e-3"/>
      <mass value="0.02"/>
      <inertia ixx="2.8169401796846998e-06" ixy="0.0" ixz="0.0" iyy="1.8687826796735248e-06" iyz="-9.755271144975289e-08" izz="2.442679644825487e-06"/>
    </inertial>
    <collision>
      <geometry>
        <mesh filename="../meshes/XL-320D.stl" scale="0.001 0.001 0.001"/>
      </geometry>
    </collision>
  </link>
  <transmission name="l_ankle_tran">
    <type>transmission_interface/SimpleTransmission</type>
    <joint name="l_ankle_joint">
      <hardwareInterface>EffortJointInterface</hardwareInterface>
    </joint>
    <actuator name="l_ankle_motor">
      <hardwareInterface>EffortJointInterface</hardwareInterface>
      <mechanicalReduction>1</mechanicalReduction>
    </actuator>
  </transmission>
  <joint name="l_ankle_spo_joint" type="fixed">
    <origin rpy="1.5707963267948966 0 0" xyz="0 0 -0.015"/>
    <parent link="l_ankle_link"/>
    <child link="l_ankle_spo_link"/>
  </joint>
  <link name="l_ankle_spo_link">
    <visual>
      <origin rpy="0 0 0" xyz="0 0 0"/>
      <geometry>
        <mesh filename="../meshes/SPO-5(GR).stl" scale="0.001 0.001 0.001"/>
      </geometry>
    </visual>
    <inertial>
      <origin rpy="0 0 0" xyz="-0.004686e-3 1.501381e-3 -0.004686e-3"/>
      <mass value="0.001"/>
      <inertia ixx="1.511699541429177e-08" ixy="-3.7907332468947e-12" ixz="1.2866184946294198e-11" iyy="2.9213253615331356e-08" iyz="-3.7907092213548e-12" izz="1.511699541429177e-08"/>
    </inertial>
    <collision>
      <geometry>
        <mesh filename="../meshes/SPO-5(GR)_s.stl" scale="0.001 0.001 0.001"/>
      </geometry>
    </collision>
  </link>
  <joint name="l_achiles_joint" type="fixed">
    <origin rpy="3.141592653589793 0 1.5707963267948966" xyz="0.0135 -0.009 0"/>
    <parent link="l_ankle_link"/>
    <child link="l_achiles_link"/>
  </joint>
  <link name="l_achiles_link">
    <visual>
      <origin rpy="0 0 0" xyz="0 0 0"/>
      <geometry>
        <mesh filename="../meshes/SPD-3B7(W).stl" scale="0.001 0.001 0.001"/>
      </geometry>
    </visual>
    <inertial>
      <origin rpy="0 0 0" xyz="0.0 0.0 0.0"/>
      <mass value="0.001"/>
      <inertia ixx="4.342770448118437e-08" ixy="0.0" ixz="0.0" iyy="2.629330586927812e-07" iyz="0.0" izz="2.215058755651781e-07"/>
    </inertial>
    <collision>
      <geometry>
        <mesh filename="../meshes/SPD-3B7(W)_s.stl" scale="0.001 0.001 0.001"/>
      </geometry>
    </collision>
  </link>
  <joint name="l_foot_anchor_joint" type="fixed">
    <origin rpy="0 0 0" xyz="0.006 0.003 0"/>
    <parent link="l_achiles_link"/>
    <child link="l_foot_anchor_link"/>
  </joint>
  <link name="l_foot_anchor_link">
    <visual>
      <origin rpy="0 0 0" xyz="0 0 0"/>
      <geometry>
        <mesh filename="../meshes/SPD-7V4(W).stl" scale="0.001 0.001 0.001"/>
      </geometry>
    </visual>
    <inertial>
      <origin rpy="0 0 0" xyz="0.0 -0.147827e-3 0.0"/>
      <mass value="0.001"/>
      <inertia ixx="3.840285715433655e-08" ixy="0.0" ixz="0.0" iyy="1.2485384525184085e-07" iyz="0.0" izz="8.815456632304686e-08"/>
    </inertial>
    <collision>
      <geometry>
        <mesh filename="../meshes/SPD-7V4(W)_s.stl" scale="0.001 0.001 0.001"/>
      </geometry>
    </collision>
  </link>
  <joint name="l_foot_axis_joint" type="fixed">
    <origin rpy="1.5707963267948966 3.141592653589793 0" xyz="0 0.0165 0"/>
    <parent link="l_foot_anchor_link"/>
    <child link="l_foot_axis_link"/>
  </joint>
  <link name="l_foot_axis_link">
    <inertial>
      <mass value="0.0001"/>
      <inertia ixx="1.0e-12" ixy="0.0" ixz="0.0" iyy="1.0e-12" iyz="0.0" izz="1.0e-12"/>
    </inertial>
  </link>
  <joint name="l_foot_joint" type="revolute">
    <axis xyz="0 0 -1"/>
    <limit effort="0.39" lower="-1.5707963267948966" upper="1.5707963267948966" velocity="11.938052083641214"/>
    <origin rpy="0 0 0" xyz="0 0 0"/>
    <parent link="l_foot_axis_link"/>
    <child link="l_foot_link"/>
    <!--
      <dynamics damping="${XL320_DAMPING}" />
      -->
  </joint>
  <link name="l_foot_link">
    <visual>
      <origin rpy="0 0 0" xyz="0 0 0"/>
      <geometry>
        <mesh filename="../meshes/XL-320D.stl" scale="0.001 0.001 0.001"/>
      </geometry>
    </visual>
    <inertial>
      <origin rpy="0 0 0" xyz="0.0 -6.745858e-3 0.697233e-3"/>
      <mass value="0.02"/>
      <inertia ixx="2.8169401796846998e-06" ixy="0.0" ixz="0.0" iyy="1.8687826796735248e-06" iyz="-9.755271144975289e-08" izz="2.442679644825487e-06"/>
    </inertial>
    <collision>
      <geometry>
        <mesh filename="../meshes/XL-320D.stl" scale="0.001 0.001 0.001"/>
      </geometry>
    </collision>
  </link>
  <transmission name="l_foot_tran">
    <type>transmission_interface/SimpleTransmission</type>
    <joint name="l_foot_joint">
      <hardwareInterface>EffortJointInterface</hardwareInterface>
    </joint>
    <actuator name="l_foot_motor">
      <hardwareInterface>EffortJointInterface</hardwareInterface>
      <mechanicalReduction>1</mechanicalReduction>
    </actuator>
  </transmission>
  <joint name="l_forefoot_joint" type="fixed">
    <origin rpy="0 0 -1.5707963267948966" xyz="-0.03 -0.009 0"/>
    <parent link="l_foot_link"/>
    <child link="l_forefoot_link"/>
  </joint>
  <link name="l_forefoot_link">
    <visual>
      <origin rpy="0 0 0" xyz="0 0 0"/>
      <geometry>
        <mesh filename="../meshes/DMF-B06(W).stl" scale="0.001 0.001 0.001"/>
      </geometry>
    </visual>
    <inertial>
      <origin rpy="0 0 0" xyz="-0.000081e-3 10.773119e-3 17.660477e-3"/>
      <mass value="0.016"/>
      <inertia ixx="1.39605976043211e-05" ixy="-9.9411880041561e-12" ixz="-4.31923961305251e-11" iyy="1.6460587803636597e-05" iyz="1.8936830969639623e-06" izz="4.50497524530975e-06"/>
    </inertial>
    <collision>
      <geometry>
        <mesh filename="../meshes/DMF-B06(W)_s.stl" scale="0.001 0.001 0.001"/>
      </geometry>
    </collision>
  </link>
  <joint name="l_sole_joint" type="fixed">
    <origin rpy="0 0 0" xyz="0 0 0.03"/>
    <parent link="l_forefoot_link"/>
    <child link="l_sole_link"/>
  </joint>
  <link name="l_sole_link">
    <visual>
      <origin rpy="0 0 0" xyz="0 0 0"/>
      <geometry>
        <mesh filename="../meshes/DMF-B07(GR).stl" scale="0.001 0.001 0.001"/>
      </geometry>
    </visual>
    <inertial>
      <origin rpy="0 0 0" xyz="0.0 0.241608e-3 0.0"/>
      <mass value="0.009"/>
      <inertia ixx="4.839947541859199e-06" ixy="0.0" ixz="0.0" iyy="6.389408983600499e-06" iyz="0.0" izz="1.5694325137204124e-06"/>
    </inertial>
    <collision>
      <geometry>
        <mesh filename="../meshes/DMF-B07(GR)_s.stl" scale="0.001 0.001 0.001"/>
      </geometry>
    </collision>
  </link>
  <joint name="r_hip_servo_joint" type="fixed">
    <origin rpy="0 0 3.141592653589793" xyz="0 -0.024 0"/>
    <parent link="r_hip_anchor_link"/>
    <child link="r_hip_servo_link"/>
  </joint>
  <link name="r_hip_servo_link">
    <visual>
      <origin rpy="0 0 0" xyz="0 0 0"/>
      <geometry>
        <mesh filename="../meshes/XL-320D.stl" scale="0.001 0.001 0.001"/>
      </geometry>
    </visual>
    <inertial>
      <origin rpy="0 0 0" xyz="0.0 -6.745858e-3 0.697233e-3"/>
      <mass value="0.02"/>
      <inertia ixx="2.8169401796846998e-06" ixy="0.0" ixz="0.0" iyy="1.8687826796735248e-06" iyz="-9.755271144975289e-08" izz="2.442679644825487e-06"/>
    </inertial>
    <collision>
      <geometry>
        <mesh filename="../meshes/XL-320D.stl" scale="0.001 0.001 0.001"/>
      </geometry>
    </collision>
  </link>
  <joint name="r_hip_joint" type="revolute">
    <axis xyz="0 0 -1"/>
    <limit effort="0.39" lower="-1.5707963267948966" upper="1.5707963267948966" velocity="11.938052083641214"/>
    <origin rpy="0 0 0" xyz="0 0 0"/>
    <parent link="r_hip_servo_link"/>
    <child link="r_hip_link"/>
    <!--
      <dynamics damping="${XL320_DAMPING}" />
      -->
  </joint>
  <link name="r_hip_link">
    <inertial>
      <mass value="0.0001"/>
      <inertia ixx="1.0e-12" ixy="0.0" ixz="0.0" iyy="1.0e-12" iyz="0.0" izz="1.0e-12"/>
    </inertial>
  </link>
  <transmission name="r_hip_tran">
    <type>transmission_interface/SimpleTransmission</type>
    <joint name="r_hip_joint">
      <hardwareInterface>EffortJointInterface</hardwareInterface>
    </joint>
    <actuator name="r_hip_motor">
      <hardwareInterface>EffortJointInterface</hardwareInterface>
      <mechanicalReduction>1</mechanicalReduction>
    </actuator>
  </transmission>
  <joint name="r_groin_joint" type="fixed">
    <origin rpy="-1.5707963267948966 0 -1.5707963267948966" xyz="0 0 0.0165"/>
    <parent link="r_hip_link"/>
    <child link="r_groin_link"/>
  </joint>
  <link name="r_groin_link">
    <visual>
      <origin rpy="0 0 0" xyz="0 0 0"/>
      <geometry>
        <mesh filename="../meshes/SPD-7V4(W).stl" scale="0.001 0.001 0.001"/>
      </geometry>
    </visual>
    <inertial>
      <origin rpy="0 0 0" xyz="0.0 -0.147827e-3 0.0"/>
      <mass value="0.001"/>
      <inertia ixx="3.840285715433655e-08" ixy="0.0" ixz="0.0" iyy="1.2485384525184085e-07" iyz="0.0" izz="8.815456632304686e-08"/>
    </inertial>
    <collision>
      <geometry>
        <mesh filename="../meshes/SPD-7V4(W)_s.stl" scale="0.001 0.001 0.001"/>
      </geometry>
    </collision>
  </link>
  <joint name="r_thigh_anchor_joint" type="fixed">
    <origin rpy="0 0 0" xyz="0 -0.003 0"/>
    <parent link="r_groin_link"/>
    <child link="r_thigh_anchor_link"/>
  </joint>
  <link name="r_thigh_anchor_link">
    <visual>
      <origin rpy="0 0 0" xyz="0 0 0"/>
      <geometry>
        <mesh filename="../meshes/SPD-3B5(W).stl" scale="0.001 0.001 0.001"/>
      </geometry>
    </visual>
    <inertial>
      <origin rpy="0 0 0" xyz="0.0 0.0 0.0"/>
      <mass value="0.001"/>
      <inertia ixx="3.042659030468979e-08" ixy="0.0" ixz="0.0" iyy="1.0920534527495155e-07" iyz="0.0" izz="8.019504918581541e-08"/>
    </inertial>
    <collision>
      <geometry>
        <mesh filename="../meshes/SPD-3B5(W)_s.stl" scale="0.001 0.001 0.001"/>
      </geometry>
    </collision>
  </link>
  <joint name="r_thigh_servo_joint" type="fixed">
    <origin rpy="3.141592653589793 0 -1.5707963267948966" xyz="-0.006 -0.0135 0"/>
    <parent link="r_thigh_anchor_link"/>
    <child link="r_thigh_servo_link"/>
  </joint>
  <link name="r_thigh_servo_link">
    <visual>
      <origin rpy="0 0 0" xyz="0 0 0"/>
      <geometry>
        <mesh filename="../meshes/XL-320D.stl" scale="0.001 0.001 0.001"/>
      </geometry>
    </visual>
    <inertial>
      <origin rpy="0 0 0" xyz="0.0 -6.745858e-3 0.697233e-3"/>
      <mass value="0.02"/>
      <inertia ixx="2.8169401796846998e-06" ixy="0.0" ixz="0.0" iyy="1.8687826796735248e-06" iyz="-9.755271144975289e-08" izz="2.442679644825487e-06"/>
    </inertial>
    <collision>
      <geometry>
        <mesh filename="../meshes/XL-320D.stl" scale="0.001 0.001 0.001"/>
      </geometry>
    </collision>
  </link>
  <joint name="r_thigh_joint" type="revolute">
    <axis xyz="0 0 1"/>
    <limit effort="0.39" lower="-1.5707963267948966" upper="1.5707963267948966" velocity="11.938052083641214"/>
    <origin rpy="0 0 0" xyz="0 0 0"/>
    <parent link="r_thigh_servo_link"/>
    <child link="r_thigh_link"/>
    <!--
      <dynamics damping="${XL320_DAMPING}" />
      -->
  </joint>
  <link name="r_thigh_link">
    <inertial>
      <mass value="0.0001"/>
      <inertia ixx="1.0e-12" ixy="0.0" ixz="0.0" iyy="1.0e-12" iyz="0.0" izz="1.0e-12"/>
    </inertial>
  </link>
  <transmission name="r_thigh_tran">
    <type>transmission_interface/SimpleTransmission</type>
    <joint name="r_thigh_joint">
      <hardwareInterface>EffortJointInterface</hardwareInterface>
    </joint>
    <actuator name="r_thigh_motor">
      <hardwareInterface>EffortJointInterface</hardwareInterface>
      <mechanicalReduction>1</mechanicalReduction>
    </actuator>
  </transmission>
  <joint name="r_thigh_spo_joint" type="fixed">
    <origin rpy="1.5707963267948966 0 0" xyz="0 0 -0.015"/>
    <parent link="r_thigh_link"/>
    <child link="r_thigh_spo_link"/>
  </joint>
  <link name="r_thigh_spo_link">
    <visual>
      <origin rpy="0 0 0" xyz="0 0 0"/>
      <geometry>
        <mesh filename="../meshes/SPO-5(GR).stl" scale="0.001 0.001 0.001"/>
      </geometry>
    </visual>
    <inertial>
      <origin rpy="0 0 0" xyz="-0.004686e-3 1.501381e-3 -0.004686e-3"/>
      <mass value="0.001"/>
      <inertia ixx="1.511699541429177e-08" ixy="-3.7907332468947e-12" ixz="1.2866184946294198e-11" iyy="2.9213253615331356e-08" iyz="-3.7907092213548e-12" izz="1.511699541429177e-08"/>
    </inertial>
    <collision>
      <geometry>
        <mesh filename="../meshes/SPO-5(GR)_s.stl" scale="0.001 0.001 0.001"/>
      </geometry>
    </collision>
  </link>
  <joint name="r_thigh_top_joint" type="fixed">
    <origin rpy="0 0 3.141592653589793" xyz="0 -0.024 0"/>
    <parent link="r_thigh_servo_link"/>
    <child link="r_thigh_top_link"/>
  </joint>
  <link name="r_thigh_top_link">
    <visual>
      <origin rpy="0 0 0" xyz="0 0 0"/>
      <geometry>
        <mesh filename="../meshes/SPU-5(W).stl" scale="0.001 0.001 0.001"/>
      </geometry>
    </visual>
    <inertial>
      <origin rpy="0 0 0" xyz="0.0 1.31172e-3 0.0"/>
      <mass value="0.001"/>
      <inertia ixx="2.7160998812739677e-08" ixy="0.0" ixz="0.0" iyy="5.2595636134718856e-08" iyz="0.0" izz="2.8058676756667802e-08"/>
    </inertial>
    <collision>
      <geometry>
        <mesh filename="../meshes/SPU-5(W)_s.stl" scale="0.001 0.001 0.001"/>
      </geometry>
    </collision>
  </link>
  <joint name="r_upper_leg_joint" type="fixed">
    <origin rpy="0 -1.5707963267948966 3.141592653589793" xyz="0 0 0"/>
    <parent link="r_thigh_link"/>
    <child link="r_upper_leg_link"/>
  </joint>
  <link name="r_upper_leg_link">
    <visual>
      <origin rpy="0 0 0" xyz="0 0 0"/>
      <geometry>
        <mesh filename="../meshes/DMF-B04(W).stl" scale="0.001 0.001 0.001"/>
      </geometry>
    </visual>
    <inertial>
      <origin rpy="0 0 0" xyz="0.0 -16.650940e-3 3.893445e-3"/>
      <mass value="0.007"/>
      <inertia ixx="1.4844145053407249e-06" ixy="0.0" ixz="0.0" iyy="1.5912567135270748e-06" iyz="3.5247996037499997e-07" izz="2.3466465586526997e-06"/>
    </inertial>
    <collision>
      <geometry>
        <mesh filename="../meshes/DMF-B04(W)_s.stl" scale="0.001 0.001 0.001"/>
      </geometry>
    </collision>
  </link>
  <joint name="r_knee_servo_joint" type="fixed">
    <origin rpy="3.141592653589793 -1.5707963267948966 0" xyz="0 -0.045 0"/>
    <parent link="r_upper_leg_link"/>
    <child link="r_knee_servo_link"/>
  </joint>
  <link name="r_knee_servo_link">
    <visual>
      <origin rpy="0 0 0" xyz="0 0 0"/>
      <geometry>
        <mesh filename="../meshes/XL-320D.stl" scale="0.001 0.001 0.001"/>
      </geometry>
    </visual>
    <inertial>
      <origin rpy="0 0 0" xyz="0.0 -6.745858e-3 0.697233e-3"/>
      <mass value="0.02"/>
      <inertia ixx="2.8169401796846998e-06" ixy="0.0" ixz="0.0" iyy="1.8687826796735248e-06" iyz="-9.755271144975289e-08" izz="2.442679644825487e-06"/>
    </inertial>
    <collision>
      <geometry>
        <mesh filename="../meshes/XL-320D.stl" scale="0.001 0.001 0.001"/>
      </geometry>
    </collision>
  </link>
  <joint name="r_knee_joint" type="revolute">
    <axis xyz="0 0 1"/>
    <limit effort="0.39" lower="-1.5707963267948966" upper="1.5707963267948966" velocity="11.938052083641214"/>
    <origin rpy="0 0 0" xyz="0 0 0"/>
    <parent link="r_knee_servo_link"/>
    <child link="r_knee_link"/>
    <!--
      <dynamics damping="${XL320_DAMPING}" />
      -->
  </joint>
  <link name="r_knee_link">
    <inertial>
      <mass value="0.0001"/>
      <inertia ixx="1.0e-12" ixy="0.0" ixz="0.0" iyy="1.0e-12" iyz="0.0" izz="1.0e-12"/>
    </inertial>
  </link>
  <transmission name="r_knee_tran">
    <type>transmission_interface/SimpleTransmission</type>
    <joint name="r_knee_joint">
      <hardwareInterface>EffortJointInterface</hardwareInterface>
    </joint>
    <actuator name="r_knee_motor">
      <hardwareInterface>EffortJointInterface</hardwareInterface>
      <mechanicalReduction>1</mechanicalReduction>
    </actuator>
  </transmission>
  <joint name="r_knee_spo_joint" type="fixed">
    <origin rpy="1.5707963267948966 0 0" xyz="0 0 -0.015"/>
    <parent link="r_knee_link"/>
    <child link="r_knee_spo_link"/>
  </joint>
  <link name="r_knee_spo_link">
    <visual>
      <origin rpy="0 0 0" xyz="0 0 0"/>
      <geometry>
        <mesh filename="../meshes/SPO-5(GR).stl" scale="0.001 0.001 0.001"/>
      </geometry>
    </visual>
    <inertial>
      <origin rpy="0 0 0" xyz="-0.004686e-3 1.501381e-3 -0.004686e-3"/>
      <mass value="0.001"/>
      <inertia ixx="1.511699541429177e-08" ixy="-3.7907332468947e-12" ixz="1.2866184946294198e-11" iyy="2.9213253615331356e-08" iyz="-3.7907092213548e-12" izz="1.511699541429177e-08"/>
    </inertial>
    <collision>
      <geometry>
        <mesh filename="../meshes/SPO-5(GR)_s.stl" scale="0.001 0.001 0.001"/>
      </geometry>
    </collision>
  </link>
  <joint name="r_lower_leg_joint" type="fixed">
    <origin rpy="-1.5707963267948966 -1.5707963267948966 0" xyz="0 0 0"/>
    <parent link="r_knee_link"/>
    <child link="r_lower_leg_link"/>
  </joint>
  <link name="r_lower_leg_link">
    <visual>
      <origin rpy="0 0 0" xyz="0 0 0"/>
      <geometry>
        <mesh filename="../meshes/DMF-B05(W).stl" scale="0.001 0.001 0.001"/>
      </geometry>
    </visual>
    <inertial>
      <origin rpy="0 0 0" xyz="0.000002e-3 6.883461e-3 17.899050e-3"/>
      <mass value="0.011"/>
      <inertia ixx="4.3095862775709e-06" ixy="0.0" ixz="0.0" iyy="5.85866900093325e-06" iyz="5.592906618791718e-07" izz="3.6828383407100998e-06"/>
    </inertial>
    <collision>
      <geometry>
        <mesh filename="../meshes/DMF-B05(W)_s.stl" scale="0.001 0.001 0.001"/>
      </geometry>
    </collision>
  </link>
  <joint name="r_ankle_axis_joint" type="fixed">
    <origin rpy="1.5707963267948966 0 1.5707963267948966" xyz="0 0 0.042"/>
    <parent link="r_lower_leg_link"/>
    <child link="r_ankle_axis_link"/>
  </joint>
  <link name="r_ankle_axis_link">
    <inertial>
      <mass value="0.0001"/>
      <inertia ixx="1.0e-12" ixy="0.0" ixz="0.0" iyy="1.0e-12" iyz="0.0" izz="1.0e-12"/>
    </inertial>
  </link>
  <joint name="r_ankle_joint" type="revolute">
    <axis xyz="0 0 1"/>
    <limit effort="0.39" lower="-1.5707963267948966" upper="1.5707963267948966" velocity="11.938052083641214"/>
    <origin rpy="0 0 0" xyz="0 0 0"/>
    <parent link="r_ankle_axis_link"/>
    <child link="r_ankle_link"/>
    <!--
      <dynamics damping="${XL320_DAMPING}" />
      -->
  </joint>
  <link name="r_ankle_link">
    <visual>
      <origin rpy="0 0 0" xyz="0 0 0"/>
      <geometry>
        <mesh filename="../meshes/XL-320D.stl" scale="0.001 0.001 0.001"/>
      </geometry>
    </visual>
    <inertial>
      <origin rpy="0 0 0" xyz="0.0 -6.745858e-3 0.697233e-3"/>
      <mass value="0.02"/>
      <inertia ixx="2.8169401796846998e-06" ixy="0.0" ixz="0.0" iyy="1.8687826796735248e-06" iyz="-9.755271144975289e-08" izz="2.442679644825487e-06"/>
    </inertial>
    <collision>
      <geometry>
        <mesh filename="../meshes/XL-320D.stl" scale="0.001 0.001 0.001"/>
      </geometry>
    </collision>
  </link>
  <transmission name="r_ankle_tran">
    <type>transmission_interface/SimpleTransmission</type>
    <joint name="r_ankle_joint">
      <hardwareInterface>EffortJointInterface</hardwareInterface>
    </joint>
    <actuator name="r_ankle_motor">
      <hardwareInterface>EffortJointInterface</hardwareInterface>
      <mechanicalReduction>1</mechanicalReduction>
    </actuator>
  </transmission>
  <joint name="r_ankle_spo_joint" type="fixed">
    <origin rpy="1.5707963267948966 0 0" xyz="0 0 -0.015"/>
    <parent link="r_ankle_link"/>
    <child link="r_ankle_spo_link"/>
  </joint>
  <link name="r_ankle_spo_link">
    <visual>
      <origin rpy="0 0 0" xyz="0 0 0"/>
      <geometry>
        <mesh filename="../meshes/SPO-5(GR).stl" scale="0.001 0.001 0.001"/>
      </geometry>
    </visual>
    <inertial>
      <origin rpy="0 0 0" xyz="-0.004686e-3 1.501381e-3 -0.004686e-3"/>
      <mass value="0.001"/>
      <inertia ixx="1.511699541429177e-08" ixy="-3.7907332468947e-12" ixz="1.2866184946294198e-11" iyy="2.9213253615331356e-08" iyz="-3.7907092213548e-12" izz="1.511699541429177e-08"/>
    </inertial>
    <collision>
      <geometry>
        <mesh filename="../meshes/SPO-5(GR)_s.stl" scale="0.001 0.001 0.001"/>
      </geometry>
    </collision>
  </link>
  <joint name="r_achiles_joint" type="fixed">
    <origin rpy="0.0 0 1.5707963267948966" xyz="-0.0135 -0.009 0"/>
    <parent link="r_ankle_link"/>
    <child link="r_achiles_link"/>
  </joint>
  <link name="r_achiles_link">
    <visual>
      <origin rpy="0 0 0" xyz="0 0 0"/>
      <geometry>
        <mesh filename="../meshes/SPD-3B7(W).stl" scale="0.001 0.001 0.001"/>
      </geometry>
    </visual>
    <inertial>
      <origin rpy="0 0 0" xyz="0.0 0.0 0.0"/>
      <mass value="0.001"/>
      <inertia ixx="4.342770448118437e-08" ixy="0.0" ixz="0.0" iyy="2.629330586927812e-07" iyz="0.0" izz="2.215058755651781e-07"/>
    </inertial>
    <collision>
      <geometry>
        <mesh filename="../meshes/SPD-3B7(W)_s.stl" scale="0.001 0.001 0.001"/>
      </geometry>
    </collision>
  </link>
  <joint name="r_foot_anchor_joint" type="fixed">
    <origin rpy="0 0 0" xyz="0.006 0.003 0"/>
    <parent link="r_achiles_link"/>
    <child link="r_foot_anchor_link"/>
  </joint>
  <link name="r_foot_anchor_link">
    <visual>
      <origin rpy="0 0 0" xyz="0 0 0"/>
      <geometry>
        <mesh filename="../meshes/SPD-7V4(W).stl" scale="0.001 0.001 0.001"/>
      </geometry>
    </visual>
    <inertial>
      <origin rpy="0 0 0" xyz="0.0 -0.147827e-3 0.0"/>
      <mass value="0.001"/>
      <inertia ixx="3.840285715433655e-08" ixy="0.0" ixz="0.0" iyy="1.2485384525184085e-07" iyz="0.0" izz="8.815456632304686e-08"/>
    </inertial>
    <collision>
      <geometry>
        <mesh filename="../meshes/SPD-7V4(W)_s.stl" scale="0.001 0.001 0.001"/>
      </geometry>
    </collision>
  </link>
  <joint name="r_foot_axis_joint" type="fixed">
    <origin rpy="1.5707963267948966 0.0 0" xyz="0 0.0165 0"/>
    <parent link="r_foot_anchor_link"/>
    <child link="r_foot_axis_link"/>
  </joint>
  <link name="r_foot_axis_link">
    <inertial>
      <mass value="0.0001"/>
      <inertia ixx="1.0e-12" ixy="0.0" ixz="0.0" iyy="1.0e-12" iyz="0.0" izz="1.0e-12"/>
    </inertial>
  </link>
  <joint name="r_foot_joint" type="revolute">
    <axis xyz="0 0 1"/>
    <limit effort="0.39" lower="-1.5707963267948966" upper="1.5707963267948966" velocity="11.938052083641214"/>
    <origin rpy="0 0 0" xyz="0 0 0"/>
    <parent link="r_foot_axis_link"/>
    <child link="r_foot_link"/>
    <!--
      <dynamics damping="${XL320_DAMPING}" />
      -->
  </joint>
  <link name="r_foot_link">
    <visual>
      <origin rpy="0 0 0" xyz="0 0 0"/>
      <geometry>
        <mesh filename="../meshes/XL-320D.stl" scale="0.001 0.001 0.001"/>
      </geometry>
    </visual>
    <inertial>
      <origin rpy="0 0 0" xyz="0.0 -6.745858e-3 0.697233e-3"/>
      <mass value="0.02"/>
      <inertia ixx="2.8169401796846998e-06" ixy="0.0" ixz="0.0" iyy="1.8687826796735248e-06" iyz="-9.755271144975289e-08" izz="2.442679644825487e-06"/>
    </inertial>
    <collision>
      <geometry>
        <mesh filename="../meshes/XL-320D.stl" scale="0.001 0.001 0.001"/>
      </geometry>
    </collision>
  </link>
  <transmission name="r_foot_tran">
    <type>transmission_interface/SimpleTransmission</type>
    <joint name="r_foot_joint">
      <hardwareInterface>EffortJointInterface</hardwareInterface>
    </joint>
    <actuator name="r_foot_motor">
      <hardwareInterface>EffortJointInterface</hardwareInterface>
      <mechanicalReduction>1</mechanicalReduction>
    </actuator>
  </transmission>
  <joint name="r_forefoot_joint" type="fixed">
    <origin rpy="0 0 1.5707963267948966" xyz="0.03 -0.009 0"/>
    <parent link="r_foot_link"/>
    <child link="r_forefoot_link"/>
  </joint>
  <link name="r_forefoot_link">
    <visual>
      <origin rpy="0 0 0" xyz="0 0 0"/>
      <geometry>
        <mesh filename="../meshes/DMF-B06(W).stl" scale="0.001 0.001 0.001"/>
      </geometry>
    </visual>
    <inertial>
      <origin rpy="0 0 0" xyz="-0.000081e-3 10.773119e-3 17.660477e-3"/>
      <mass value="0.016"/>
      <inertia ixx="1.39605976043211e-05" ixy="-9.9411880041561e-12" ixz="-4.31923961305251e-11" iyy="1.6460587803636597e-05" iyz="1.8936830969639623e-06" izz="4.50497524530975e-06"/>
    </inertial>
    <collision>
      <geometry>
        <mesh filename="../meshes/DMF-B06(W)_s.stl" scale="0.001 0.001 0.001"/>
      </geometry>
    </collision>
  </link>
  <joint name="r_sole_joint" type="fixed">
    <origin rpy="0 0 0" xyz="0 0 0.03"/>
    <parent link="r_forefoot_link"/>
    <child link="r_sole_link"/>
  </joint>
  <link name="r_sole_link">
    <visual>
      <origin rpy="0 0 0" xyz="0 0 0"/>
      <geometry>
        <mesh filename="../meshes/DMF-B07(GR).stl" scale="0.001 0.001 0.001"/>
      </geometry>
    </visual>
    <inertial>
      <origin rpy="0 0 0" xyz="0.0 0.241608e-3 0.0"/>
      <mass value="0.009"/>
      <inertia ixx="4.839947541859199e-06" ixy="0.0" ixz="0.0" iyy="6.389408983600499e-06" iyz="0.0" izz="1.5694325137204124e-06"/>
    </inertial>
    <collision>
      <geometry>
        <mesh filename="../meshes/DMF-B07(GR)_s.stl" scale="0.001 0.001 0.001"/>
      </geometry>
    </collision>
  </link>
  <!-- KLAMP'T XTRA LINES-->
  <klampt use_vis_geom="1"/>  <!--freeze_root_link="1"-->                        
</robot>
